Workbook

Sheet Summary
A1: Bikeways Dashboard
A2: CDOT Bike Program
A5: Total Network
B6: Miles
B7: Centerline | C7: Lane
A8: Protected Bike Lanes | B8: =SUMIFS(Network!$AB$11:$AB$1010,Network!$N$11:$N$1010,$D8) -> 38.508661 | C8: =SUMIFS(Network!$AC$11:$AC$1010,Network!$N$11:$N$1010,$D8) -> 74.047352 | D8: PROTECTED BIKE LANE
A9: Buffered Bike Lanes | B9: =SUMIFS(Network!$AB$11:$AB$1010,Network!$N$11:$N$1010,$D9) -> 115.5746 | C9: =SUMIFS(Network!$AC$11:$AC$1010,Network!$N$11:$N$1010,$D9) -> 218.44582 | D9: BUFFERED BIKE LANE
A10: Bike Lanes | B10: =SUMIFS(Network!$AB$11:$AB$1010,Network!$N$11:$N$1010,$D10) -> 125.09298 | C10: =SUMIFS(Network!$AC$11:$AC$1010,Network!$N$11:$N$1010,$D10) -> 240.3812 | D10: BIKE LANE
A11: Neighborhood Greenways | B11: =SUMIFS(Network!$AB$11:$AB$1010,Network!$N$11:$N$1010,$D11) -> 37.912126 | C11: =SUMIFS(Network!$AC$11:$AC$1010,Network!$N$11:$N$1010,$D11) -> 67.020481 | D11: NEIGHBORHOOD GREENWAY
A12: Marked Shared Lanes | B12: =SUMIFS(Network!$AB$11:$AB$1010,Network!$N$11:$N$1010,$D12) -> 49.985623 | C12: =SUMIFS(Network!$AC$11:$AC$1010,Network!$N$11:$N$1010,$D12) -> 98.506151 | D12: SHARED-LANE
A13: TOTAL ON-STREET | B13: =SUM(B8:B12) -> 367.07398 | C13: =SUM(C8:C12) -> 698.40101
A15: Off Street Trail | B15: 5.8 | C15: 5.8 | D15: OFF-STREET TRAIL
A16: Access Path | B16: 49.5 | C16: 49.5 | D16: ACCESS PATH
A17: TOTAL TRAILS | B17: =SUM(B15:B16) -> 55.3 | C17: =SUM(C15:C16) -> 55.3
A19: TOTAL NETWORK | B19: =SUM(B13,B17) -> 422.37398 | C19: =SUM(C13,C17) -> 753.70101
A22: Bikeways
C24: Emanuel 1 | G24: Emanuel 2 | K24: Lightfoot 1 | O24: Johnson 1
A26: Total Network by Year | T26: Centerline Miles
B27: 2010 | C27: 2011 | D27: 2012 | E27: 2013 | F27: 2014 | G27: 2015 | H27: 2016 | I27: 2017 | J27: 2018 | K27: 2019 | L27: 2020 | M27: 2021 | N27: 2022 | O27: 2023 | P27: 2024 | Q27: 2025 | R27: 2026 | S27: 2027 | T27: 2028 | AB27: 1. Bikeways
A28: Protected Bike Lanes | B28: =C28-C74 -> 0 | C28: 2 | D28: 11.4 | E28: 15.5 | F28: 18.5 | G28: 21.35 | H28: 22.55 | I28: 22.5 | J28: 23.45068 | K28: 24.3 | L28: 26.7 | M28: 35.220585 | N28: 37.56 | O28: 47.2 | V28: 2010 Best Guess/2011 Year in Review existing network | AB28: Total Network
A29: Buffered Bike Lanes | B29: =C29-C75 -> 0 | C29: 1 | D29: 18.65 | E29: 33.5 | F29: 67 | G29: 87 | H29: 88.8 | I29: =94.5+0.6 -> 95.1 | J29: 105.88543 | K29: 107.5 | L29: 110.5 | M29: 113.96737 | N29: 115.57 | O29: 110.1 | V29: 2011-2015, 2017 Year in Reviews (YiR mileage are estimates) | AB29: Total Network by Year
A30: Bike Lanes | B30: =C30-C76 -> 116 | C30: =116+17 -> 133 | D30: 134.2 | E30: 117.5 | F30: 99 | G30: 88.5 | H30: =AVERAGE(G30,I30) -> 85.6 | I30: =82.1+1.2-0.6 -> 82.7 | J30: 83.228266 | K30: 88 | L30: 103.3 | M30: 113.05001 | N30: 126.1 | O30: 130.4 | V30: 2016 Best Guess | AB30: Installs
A31: Neighborhood Greenways | B31: =C31-C77 -> 0 | E31: 1 | F31: 1.5 | G31: 1.5 | H31: 2.1 | I31: 3.2 | J31: 11.448655 | K31: 14.4 | L31: 17.4 | M31: 26.850629 | N31: 39.17 | O31: 57.2 | V31: 2017 +0.6 Dearborn - River to Chicago BBL Upgrade | AB31: Annual Miles Installed (centerline) (new & restriped)
A32: Marked Shared Lanes | B32: =C32-C78 -> 30 | C32: =30+9 -> 39 | D32: 39.85 | E32: 40 | F32: 41.5 | G32: 45.7 | H32: 45.7 | I32: 45.4 | J32: 45.474801 | K32: 44.4 | L32: 44.9 | M32: 52.026725 | N32: 49.74 | O32: 48.3 | V32: 2018 - updated with actual installations installed | AB32: Annual Miles Installed (lane) (new & restriped)
A33: TOTAL | B33: =SUM(B28:B32) -> 146 | C33: =SUM(C28:C32) -> 175 | D33: =SUM(D28:D32) -> 204.1 | E33: =SUM(E28:E32) -> 207.5 | F33: =SUM(F28:F32) -> 227.5 | G33: =SUM(G28:G32) -> 244.05 | H33: =SUM(H28:H32) -> 244.75 | I33: =SUM(I28:I32) -> 248.9 | ... T33: =SUM(T28:T32) -> 0 | AB33: Spending
AB34: Average Age
A35: Network Growth (Change from Prev Yr) | C35: =C33-B33 -> 29 | D35: =D33-C33 -> 29.1 | E35: =E33-D33 -> 3.4 | F35: =F33-E33 -> 20 | G35: =G33-F33 -> 16.55 | H35: =H33-G33 -> 0.7 | I35: =I33-H33 -> 4.15 | J35: =J33-I33 -> 20.587835 | ... T35: =T33-S33 -> 0 | AB35: Population within 1/2 mile of Bikeway
C37: E1 Average | F37: =AVERAGE(C35:F35) -> 20.375 | G37: E2 Average | J37: =AVERAGE(G35:J35) -> 10.496959 | K37: L1 Average | N37: =AVERAGE(K35:N35) -> 24.663041 | AB37: 2. Mode Share
G38: E1+2 Average | J38: =AVERAGE(C35:J35) -> 15.435979
B39: 0 | F39: =F33-B33 -> 81.5 | J39: =J33-F33 -> 41.987835 | N39: =N33-J33 -> 98.652165 | AB39: 3. Crashes
AB40: Annual Crashes by Mode & Severity
A41: Total Network by Year with Trails | P41: Centerline Miles | AB41: Crashes per 10,000 bike commuters
B42: 2010 | C42: 2011 | D42: 2012 | E42: 2013 | F42: 2014 | G42: 2015 | H42: 2016 | I42: 2017 | J42: 2018 | K42: 2019 | L42: 2020 | M42: 2021 | N42: 2022 | O42: 2023 | P42: 2024 | Q42: 2025 | R42: 2026 | S42: 2027 | T42: 2028
A43: Marked Shared Lanes | B43: 30 | C43: =30+9 -> 39 | D43: 39.85 | E43: 40 | F43: 41.5 | G43: 45.7 | H43: 45.7 | I43: 45.4 | J43: 45.474801 | K43: 44.4 | L43: 44.9 | M43: 52.026725 | N43: =N32 -> 49.74 | O43: 48.3 | P43: =P32 -> 0 | Q43: =Q32 -> 0 | R43: =R32 -> 0 | S43: =S32 -> 0 | T43: =T32 -> 0
A44: Bike Lanes | B44: 116 | C44: =116+17 -> 133 | D44: 134.2 | E44: 117.5 | F44: 99 | G44: 88.5 | H44: =AVERAGE(G44,I44) -> 85.6 | I44: =82.1+1.2-0.6 -> 82.7 | J44: 83.228266 | K44: 88 | L44: 103.3 | M44: 113.05001 | N44: =N30 -> 126.1 | O44: 130.4 | P44: =P30 -> 0 | Q44: =Q30 -> 0 | R44: =R30 -> 0 | S44: =S30 -> 0 | T44: =T30 -> 0
A45: Buffered Bike Lanes | B45: 0 | C45: 1 | D45: 18.65 | E45: 33.5 | F45: 67 | G45: 87 | H45: 88.8 | I45: =94.5+0.6 -> 95.1 | J45: 105.88543 | K45: 107.5 | L45: 110.5 | M45: 113.96737 | N45: =N29 -> 115.57 | O45: 110.1 | P45: =P29 -> 0 | Q45: =Q29 -> 0 | R45: =R29 -> 0 | S45: =S29 -> 0 | T45: =T29 -> 0
A46: Neighborhood Greenways | B46: 0 | E46: 1 | F46: 1.5 | G46: 1.5 | H46: 2.1 | I46: 3.2 | J46: 11.448655 | K46: 14.4 | L46: 17.4 | M46: 26.850629 | N46: =N31 -> 39.17 | O46: 57.2 | P46: =P31 -> 0 | Q46: =Q31 -> 0 | R46: =R31 -> 0 | S46: =S31 -> 0 | T46: =T31 -> 0
A47: Protected Bike Lanes | B47: 0 | C47: 2 | D47: 11.4 | E47: 15.5 | F47: 18.5 | G47: 21.35 | H47: 22.55 | I47: 22.5 | J47: 23.45068 | K47: 24.3 | L47: 26.7 | M47: 35.220585 | N47: =N28 -> 37.56 | O47: 47.2 | P47: =P28 -> 0 | Q47: =Q28 -> 0 | R47: =R28 -> 0 | S47: =S28 -> 0 | T47: =T28 -> 0
A48: Off-Street Trails | B48: 47.2 | C48: 47.2 | D48: 47.76 | E48: 47.76 | F48: 47.76 | G48: 51.53 | H48: 51.81 | I48: 54.62 | J48: 54.92 | K48: 54.92 | L48: 55.27 | M48: 55.27 | N48: 55.27 | O48: 55.3 | P48: 55.27 | Q48: 55.27 | R48: 55.27 | S48: 55.27 | T48: 55.27
A49: TOTAL | B49: =SUM(B43:B48) -> 193.2 | C49: =SUM(C43:C48) -> 222.2 | D49: =SUM(D43:D48) -> 251.86 | E49: =SUM(E43:E48) -> 255.26 | F49: =SUM(F43:F48) -> 275.26 | G49: =SUM(G43:G48) -> 295.58 | H49: =SUM(H43:H48) -> 296.56 | I49: =SUM(I43:I48) -> 303.52 | ... T49: =SUM(T43:T48) -> 55.27
...

Sheet Network
A1: Chicago Bike Network
A2: CDOT Bike Program
B4: 44893 | C4: Date of GIS export
AE8: Formula for MI_LANE
A9: FID | B9: STREET | C9: PRE_DIR | D9: ST_NAME | E9: ST_TYPE | F9: ONEWAY_DIR | G9: L_F_ADDR | H9: R_F_ADDR | I9: F_STREET | J9: L_T_ADDR | K9: R_T_ADDR | L9: T_STREET | M9: CLASS | O9: BIKEROUTE | P9: INST_TYPE | Q9: PROJECT_ID | R9: INST_PRO | S9: INST_YR | T9: INST_MO | U9: INST_NOTES | V9: MAIN_PRO | W9: MAIN_YR | X9: MAIN_MO | Y9: MAIN_NOTES | Z9: RESTRIPED | AA9: RESURFACED | AB9: MI_CTRLINE | AC9: MI_LANE | AD9: BR_NAME | AE9: BR_ONEWAY | AF9: BR_OW_DIR | AG9: CONTRAFLOW | AH9: PBL_ADJ_TW | AI9: PBL_PROTEC | AJ9: PASSING | AK9: CONC_PVMT | AL9: CONC_YR | AM9: EQUITY_N | AN9: EQUITY_NW | AO9: EQUITY_W | AP9: EQUITY_S | AQ9: EQUITY_SW | AR9: EQUITY_FS | AS9: EQUITY_C
A10: FID | B10: STREET | C10: PRE_DIR | D10: ST_NAME | E10: ST_TYPE | F10: ONEWAY_DIR | G10: L_F_ADDR | H10: R_F_ADDR | I10: F_STREET | J10: L_T_ADDR | K10: R_T_ADDR | L10: T_STREET | M10: CLASS | N10: DISPLAYROU | O10: BIKEROUTE | P10: INST_TYPE | Q10: PROJECT_ID | R10: INST_PRO | S10: INST_YR | T10: INST_MO | U10: INST_NOTES | V10: MAIN_PRO | W10: MAIN_YR | X10: MAIN_MO | Y10: MAIN_NOTES | Z10: RESTRIPED | AA10: RESURFACED | AB10: MI_CTRLINE | AC10: MI_LANE | AD10: BR_NAME | AE10: BR_ONEWAY | AF10: BR_OW_DIR | AG10: CONTRAFLOW | AH10: PBL_ADJ_TW | AI10: PBL_PROTEC | AJ10: PASSING | AK10: CONC_PVMT | AL10: CONC_YR | AM10: EQUITY_N | AN10: EQUITY_NW | AO10: EQUITY_W | AP10: EQUITY_S | AQ10: EQUITY_SW | AR10: EQUITY_FS | AS10: EQUITY_C | AT10: EQUITY CHECK | AU10: EDIT_DATE_ | AV10: EDIT_QA | AW10: Curbside | AX10: NETWORKTYP | AY10: ROUTE_TYPE | AZ10: S_Speed
A11: 0 | B11: MARQUETTE RD | C11: W | D11: MARQUETTE | E11: RD | F11: - | G11: 3201 | H11: 3200 | I11: S CENTRAL PARK AVE | J11: 3557 | K11: 3556 | L11: S KEDZIE AVE | M11: 3 | N11: BUFFERED BIKE LANE | O11: BUFFERED BIKE LANE | P11: UPGRADE | Q11: 2002-17 | R11: STP RESURFACING | S11: 2019 | T11: 0 | U11: EB curbside | V11: BIKE LANE RESTRIPING 2020 | W11: 2020 | X11: 0 | Z11: 2020 | AA11: 2019 | AB11: 0.49516973 | AC11: 0.99033947 | AD11: - | AE11: N | AF11: - | AG11: - | AH11: - | AI11: - | AJ11: - | AK11: - | AL11: 0 | AM11: 0 | AN11: 0 | AO11: 0 | AP11: 0 | AQ11: 1 | AR11: 0 | AS11: 0 | AT11: =SUM(AM11:AS11) -> 1 | AU11: 04.07.2022 | AV11: JP | AW11: Y | AX11: 2 | AY11: Arterial
A12: 1 | B12: MARQUETTE RD | C12: W | D12: MARQUETTE | E12: RD | F12: - | G12: 3159 | H12: 3158 | I12: S KEDZIE AVE | J12: 3001 | K12: 3000 | L12: S SACRAMENTO AVE | M12: 3 | N12: SHARED-LANE | O12: SHARED-LANE | P12: MAINTAIN | Q12: 2002-17 | R12: STP RESURFACING | S12: 2019 | T12: 0 | V12: BIKE LANE RESTRIPING 2020 | W12: 2020 | X12: 0 | Z12: 2020 | AA12: 2019 | AB12: 0.25240306 | AC12: 0.50480611 | AD12: - | AE12: N | AF12: - | AG12: - | AH12: - | AI12: - | AJ12: - | AK12: - | AL12: 0 | AM12: 0 | AN12: 0 | AO12: 0 | AP12: 0 | AQ12: 1 | AR12: 0 | AS12: 0 | AT12: =SUM(AM12:AS12) -> 1 | AU12: 44658 | AV12: JP | AW12: - | AX12: 2 | AY12: Arterial | AZ12: -
A13: 2 | B13: 18TH ST | C13: W | D13: 18TH | E13: ST | G13: 1901 | H13: 1900 | I13: S DAMEN AVE | J13: 1401 | K13: 1400 | L13: S LOOMIS ST | M13: 3 | N13: BIKE LANE | O13: BIKE LANE | P13: NEW | Q13: 2011-3 | R13: CMAQ 2009 | S13: 2011 | T13: 6 | V13: Divvy Restriping | W13: 2018 | X13: 7 | Z13: 2018 | AA13: 0 | AB13: 0.75732065 | AC13: 1.5146413 | AE13: N | AL13: 0 | AM13: 0 | AN13: 0 | AO13: 0 | AP13: 0 | AQ13: 0 | AR13: 0 | AS13: 1 | AT13: =SUM(AM13:AS13) -> 1 | AU13: 43322 | AV13: JP | AX13: 2 | AY13: Arterial
A14: 3 | B14: LAKE SHORE DR | C14: S | D14: LAKE SHORE | E14: DR | G14: 8100 | H14: 8101 | I14: E 81ST ST | J14: 8700 | K14: 8701 | L14: E 87TH ST | M14: 2 | N14: BUFFERED BIKE LANE | O14: BUFFERED BIKE LANE | P14: NEW | Q14: 2013-9 | R14: US 41 EXTENSION | S14: 2013 | T14: 10 | U14: RESURFACED | W14: 0 | X14: 0 | Z14: 2013 | AA14: 2013 | AB14: 0.75430901 | AC14: 1.508618 | AE14: N | AL14: 0 | AM14: 0 | AN14: 0 | AO14: 0 | AP14: 1 | AQ14: 0 | AR14: 0 | AS14: 0 | AT14: =SUM(AM14:AS14) -> 1 | AU14: 12.08.2020 | AV14: JP | AW14: N | AX14: 2 | AY14: Arterial
A15: 4 | B15: LAKE ST | C15: W | D15: LAKE | E15: ST | F15: - | G15: 3200 | H15: 3201 | I15: N KEDZIE AVE | J15: 2000 | K15: 2001 | L15: N DAMEN AVE | M15: 3 | N15: PROTECTED BIKE LANE | O15: PROTECTED BIKE LANE | P15: UPGRADE | Q15: 2012-24 | R15: AR 21 - FED | S15: 2022 | T15: 11 | W15: 0 | X15: 0 | Z15: 2022 | AA15: 2022 | AB15: 1.5227683 | AC15: 3.0455366 | AD15: - | AE15: N | AF15: - | AG15: - | AH15: N | AI15: CONCRETE | AJ15: - | AK15: - | AL15: 0 | AM15: 0 | AN15: 0 | AO15: 0.5 | AP15: 0 | AQ15: 0 | AR15: 0 | AS15: 0.5 | AT15: =SUM(AM15:AS15) -> 1 | AU15: 11.17.2022 | AV15: JP | AW15: Y | AX15: 1 | AY15: Arterial | AZ15: 30
A16: 5 | B16: WELLS ST | C16: S | D16: WELLS | E16: ST | F16: S | G16: 351 | H16: 350 | I16: W VAN BUREN ST | J16: 151 | K16: 150 | L16: W ARCADE PL | M16: 4 | N16: SHARED-LANE | O16: SHARED-LANE | P16: NEW | Q16: 2012-28 | R16: BIKE PRGM 12 | S16: 2012 | T16: 6 | W16: 0 | X16: 0 | Z16: 2012 | AA16: 0 | AB16: 0.30683475 | AC16: 0.30683475 | AE16: Y | AF16: S | AG16: N | AL16: 0 | AM16: 0 | AN16: 0 | AO16: 0 | AP16: 0 | AQ16: 0 | AR16: 0 | AS16: 1 | AT16: =SUM(AM16:AS16) -> 1 | AU16: 43328 | AV16: JP | AX16: 2 | AY16: Arterial
A17: 6 | B17: 55TH PL | C17: E | D17: 55TH | E17: PL | F17: W | G17: 1400 | H17: 1401 | I17: S DORCHESTER AVE | J17: 1464 | K17: 1463 | L17: E 55TH ST | M17: 2 | N17: BUFFERED BIKE LANE | O17: BUFFERED BIKE LANE | P17: NEW | R17: BIKE PRGM 12 | S17: 2012 | T17: 7 | U17: ROAD DIET | V17: CDOT RESTRIPING | W17: 2017 | X17: 6 | Z17: 2017 | AA17: 0 | AB17: 0.1405204 | AC17: 0.1405204 | AE17: Y | AF17: W | AG17: N | AL17: 0 | AM17: 0 | AN17: 0 | AO17: 0 | AP17: 1 | AQ17: 0 | AR17: 0 | AS17: 0 | AT17: =SUM(AM17:AS17) -> 1 | AU17: 43328 | AV17: JP | AW17: N | AX17: 2 | AY17: Arterial
A18: 7 | B18: 55TH PL | C18: E | D18: 55TH | E18: PL | F18: E | G18: 1366 | H18: 1351 | I18: E 55TH ST | J18: 1390 | K18: 1391 | L18: S DORCHESTER AVE | M18: 2 | N18: PROTECTED BIKE LANE | O18: PROTECTED BIKE LANE | P18: UPGRADE | R18: AR 18 | S18: 2019 | T18: 5 | U18: RESURFACED, CONCRETE UPGRADES | W18: 0 | X18: 0 | Z18: 2019 | AA18: 2019 | AB18: 0.04569508 | AC18: 0.04569508 | AE18: Y | AF18: E | AG18: N | AI18: NONE | AJ18: - | AL18: 0 | AM18: 0 | AN18: 0 | AO18: 0 | AP18: 1 | AQ18: 0 | AR18: 0 | AS18: 0 | AT18: =SUM(AM18:AS18) -> 1 | AU18: 10.25.2022 | AV18: JP | AW18: - | AX18: 1 | AY18: Arterial
A19: 8 | B19: WABASH AVE | C19: S | D19: WABASH | E19: AVE | G19: 898 | H19: 899 | I19: E 9TH ST | J19: 601 | K19: 600 | L19: E HARRISON ST | M19: 4 | N19: BUFFERED BIKE LANE | O19: BUFFERED BIKE LANE | P19: NEW | Q19: 2012-27 | R19: BIKE PRGM 12 | S19: 2012 | T19: 7 | U19: ROAD DIET | V19: BIKE LANE RESTRIPING 2020 | W19: 2020 | X19: 0 | Z19: 2020 | AA19: 0 | AB19: 0.26595669 | AC19: 0.53191339 | AE19: N | AL19: 0 | AM19: 0 | AN19: 0 | AO19: 0 | AP19: 0 | AQ19: 0 | AR19: 0 | AS19: 1 | AT19: =SUM(AM19:AS19) -> 1 | AU19: 12.08.2020 | AV19: JP | AW19: N | AX19: 2 | AY19: Arterial
A20: 9 | B20: JACKSON BLVD | C20: W | D20: JACKSON | E20: BLVD | G20: 3787 | H20: 3786 | I20: S HAMLIN BLVD | J20: 3601 | K20: 3600 | L20: S CENTRAL PARK BLVD | M20: 4 | N20: PROTECTED BIKE LANE | O20: PROTECTED BIKE LANE | P20: NEW | R20: BIKE PRGM 12 | S20: 2012 | T20: 6 | U20: ROAD DIET | V20: DIVVY 18 | W20: 2018 | X20: 5 | Z20: 2018 | AA20: 0 | AB20: 0.25049819 | AC20: 0.50099637 | AE20: N | AF20: - | AG20: - | AH20: - | AI20: POST | AJ20: - | AK20: Y | AL20: 2018 | AM20: 0 | AN20: 0 | AO20: 1 | AP20: 0 | AQ20: 0 | AR20: 0 | AS20: 0 | AT20: =SUM(AM20:AS20) -> 1 | AU20: 05.18.2022 | AV20: JP | AW20: Y | AX20: 1 | AY20: Arterial
A21: 10 | B21: ELSTON AVE | C21: N | D21: ELSTON | E21: AVE | G21: 828 | H21: 825 | I21: N MILWAUKEE AVE | J21: 874 | K21: 871 | L21: W CHESTNUT ST | M21: 3 | N21: BUFFERED BIKE LANE | O21: BUFFERED BIKE LANE | P21: UPGRADE | R21: AR 11 | S21: 2012 | T21: 6 | U21: RESURFACED | W21: 0 | X21: 0 | Z21: 2012 | AA21: 2012 | AB21: 0.096969646 | AC21: 0.19393929 | AE21: N | AL21: 0 | AM21: 0 | AN21: 0 | AO21: 0 | AP21: 0 | AQ21: 0 | AR21: 0 | AS21: 1 | AT21: =SUM(AM21:AS21) -> 1 | AU21: 43332 | AV21: JP | AW21: N | AX21: 2 | AY21: Arterial
A22: 11 | B22: HALSTED ST | C22: N | D22: HALSTED | E22: ST | G22: 2000 | H22: 2001 | I22: W ARMITAGE AVE | J22: 2200 | K22: 2201 | L22: W WEBSTER AVE | M22: 2 | N22: BIKE LANE | O22: BIKE LANE | P22: NEW | R22: BIKE PRGM 00 | S22: 2000 | T22: 7 | V22: AR 17 | W22: 2018 | X22: 9 | Y22: RESURFACED | Z22: 2018 | AA22: 2018 | AB22: 0.25112071 | AC22: 0.50224143 | AE22: N | AL22: 0 | AM22: 1 | AN22: 0 | AO22: 0 | AP22: 0 | AQ22: 0 | AR22: 0 | AS22: 0 | AT22: =SUM(AM22:AS22) -> 1 | AU22: 43333 | AV22: JP | AX22: 2 | AY22: Arterial
A23: 12 | B23: HALSTED ST | C23: N | D23: HALSTED | E23: ST | G23: 2800 | H23: 2801 | I23: W DIVERSEY PKWY | J23: 3000 | K23: 3001 | L23: W WELLINGTON AVE | M23: 2 | N23: BUFFERED BIKE LANE | O23: BUFFERED BIKE LANE | P23: UPGRADE | Q23: 2004-8 | R23: EMERGENCY REPAIR PROGRAM | S23: 2012 | T23: 7 | U23: RESURFACED | V23: MAINTENANCE 2020 | W23: 2020 | X23: 0 | Z23: 2020 | AA23: 2012 | AB23: 0.25265117 | AC23: 0.50530235 | AE23: N | AL23: 0 | AM23: 1 | AN23: 0 | AO23: 0 | AP23: 0 | AQ23: 0 | AR23: 0 | AS23: 0 | AT23: =SUM(AM23:AS23) -> 1 | AU23: 08.28.2020 | AV23: JP | AW23: N | AX23: 2 | AY23: Arterial
A24: 13 | B24: CALIFORNIA AVE | C24: S | D24: CALIFORNIA | E24: AVE | G24: 2411 | H24: 2412 | I24: W 24TH BLVD | J24: 2200 | K24: 2201 | L24: W CERMAK RD | M24: 3 | N24: BIKE LANE | O24: BIKE LANE | P24: NEW | R24: CMAQ V(2) | S24: 2007 | T24: 10 | V24: Divvy 18 | W24: 2018 | X24: 9 | Z24: 2018 | AA24: 2012 | AB24: 0.27746195 | AC24: 0.55492389 | AE24: N | AL24: 0 | AM24: 0 | AN24: 0 | AO24: 1 | AP24: 0 | AQ24: 0 | AR24: 0 | AS24: 0 | AT24: =SUM(AM24:AS24) -> 1 | AU24: 43335 | AV24: JP | AX24: 2 | AY24: Arterial
A25: 14 | B25: MARQUETTE RD | C25: E | D25: MARQUETTE | E25: RD | G25: 500 | H25: 501 | I25: S EBERHART AVE | J25: 800 | K25: 801 | L25: S COTTAGE GROVE AVE | M25: 3 | N25: BIKE LANE | O25: BIKE LANE | P25: NEW | R25: CMAQ IV | S25: 2003 | T25: 7 | V25: Bike Program Maintenance 2021 | W25: 2021 | X25: 0 | Z25: 2021 | AA25: 2011 | AB25: 0.37651479 | AC25: 0.75302959 | AE25: N | AF25: - | AG25: - | AH25: - | AI25: - | AJ25: - | AK25: - | AL25: 0 | AM25: 0 | AN25: 0 | AO25: 0 | AP25: 1 | AQ25: 0 | AR25: 0 | AS25: 0 | AT25: =SUM(AM25:AS25) -> 1 | AU25: 03.24.2022 | AV25: JP | AW25: Y | AX25: 2 | AY25: Arterial
A26: 15 | B26: WASHINGTON BLVD | C26: W | D26: WASHINGTON | E26: BLVD | F26: E | G26: 725 | H26: 726 | I26: N HALSTED ST | J26: 723 | K26: 724 | L26: I-90/94 | M26: 4 | N26: BUFFERED BIKE LANE | O26: BUFFERED BIKE LANE | P26: UPGRADE | Q26: 2006-8 | R26: LOOP LINK | S26: 2018 | T26: 6 | W26: 0 | X26: 0 | Z26: 2018 | AA26: 2012 | AB26: 0.051135638 | AC26: 0.051135638 | AD26: LOOP LINK | AE26: Y | AF26: E | AG26: N | AL26: 0 | AM26: 0 | AN26: 0 | AO26: 0 | AP26: 0 | AQ26: 0 | AR26: 0 | AS26: 1 | AT26: =SUM(AM26:AS26) -> 1 | AU26: 43335 | AV26: JP | AW26: N | AX26: 2 | AY26: Arterial
A27: 16 | B27: OAKWOOD BLVD | C27: E | D27: OAKWOOD | E27: BLVD | G27: 376 | H27: 377 | I27: S DR MARTIN LUTHER KING JR DR | J27: 530 | K27: 531 | L27: S VINCENNES AVE | M27: 3 | N27: BIKE LANE | O27: BIKE LANE | P27: NEW | R27: CMAQ III | S27: 2002 | T27: 7 | V27: VZ2018 | W27: 2018 | X27: 8 | Z27: 2018 | AA27: 2009 | AB27: 0.21007186 | AC27: 0.42014373 | AE27: N | AL27: 0 | AM27: 0 | AN27: 0 | AO27: 0 | AP27: 1 | AQ27: 0 | AR27: 0 | AS27: 0 | AT27: =SUM(AM27:AS27) -> 1 | AU27: 43335 | AV27: JP | AX27: 2 | AY27: Arterial
A28: 17 | B28: OAKWOOD BLVD | C28: E | D28: OAKWOOD | E28: BLVD | G28: 536 | H28: 537 | I28: S VINCENNES AVE | J28: 650 | K28: 649 | L28: S LANGLEY AVE | M28: 3 | N28: BIKE LANE | O28: BIKE LANE | P28: NEW | R28: CMAQ III | S28: 2002 | T28: 7 | V28: UTILITY | W28: 2017 | X28: 10 | Y28: RESURFACED | Z28: 2017 | AA28: 2017 | AB28: 0.15975541 | AC28: 0.31951083 | AE28: N | AL28: 0 | AM28: 0 | AN28: 0 | AO28: 0 | AP28: 1 | AQ28: 0 | AR28: 0 | AS28: 0 | AT28: =SUM(AM28:AS28) -> 1 | AU28: 43335 | AV28: JP | AX28: 2 | AY28: Arterial
A29: 18 | B29: OAKWOOD BLVD | C29: E | D29: OAKWOOD | E29: BLVD | G29: 700 | H29: 701 | I29: S LANGLEY AVE | J29: 768 | K29: 773 | L29: S COTTAGE GROVE AVE | M29: 3 | N29: BIKE LANE | O29: BIKE LANE | P29: NEW | R29: CMAQ III | S29: 2002 | T29: 7 | V29: UTILITY | W29: 2017 | X29: 10 | Y29: RESURFACED | Z29: 2017 | AA29: 2017 | AB29: 0.1521576 | AC29: 0.3043152 | AE29: N | AL29: 0 | AM29: 0 | AN29: 0 | AO29: 0 | AP29: 1 | AQ29: 0 | AR29: 0 | AS29: 0 | AT29: =SUM(AM29:AS29) -> 1 | AU29: 43335 | AV29: JP | AX29: 2 | AY29: Arterial
A30: 19 | B30: ALBION AVE | C30: W | D30: ALBION | E30: AVE | F30: E | G30: 1253 | H30: 1252 | I30: N LAKEWOOD AVE | J30: 1200 | K30: 1201 | L30: N SHERIDAN RD | M30: 4 | N30: NEIGHBORHOOD GREENWAY | O30: SHARED-LANE | P30: NEW | R30: BIKE PRGM 12 | S30: 2012 | T30: 7 | U30: WB CONTRAFLOW LANE | W30: 0 | X30: 0 | Z30: 2012 | AA30: 0 | AB30: 0.25067333 | AC30: 0.50134666 | AE30: N | AG30: Y | AL30: 0 | AM30: 1 | AN30: 0 | AO30: 0 | AP30: 0 | AQ30: 0 | AR30: 0 | AS30: 0 | AT30: =SUM(AM30:AS30) -> 1 | AU30: 08.28.2020 | AV30: JP | AX30: 3 | AY30: Neighborhood
A31: 20 | B31: HALSTED ST | C31: S | D31: HALSTED | E31: ST | G31: 7401 | H31: 7400 | I31: W 74TH ST | J31: 6901 | K31: 6900 | L31: W 69TH ST | M31: 2 | N31: BUFFERED BIKE LANE | O31: BUFFERED BIKE LANE | P31: NEW | Q31: 2012-19 | R31: AR 11 | S31: 2012 | T31: 7 | U31: RESURFACED | W31: 0 | X31: 0 | Z31: 2012 | AA31: 2012 | AB31: 0.62727999 | AC31: 1.25456 | AE31: N | AL31: 0 | AM31: 0 | AN31: 0 | AO31: 0 | AP31: 0 | AQ31: 1 | AR31: 0 | AS31: 0 | AT31: =SUM(AM31:AS31) -> 1 | AU31: 08.28.2020 | AV31: JP | AW31: N | AX31: 2 | AY31: Arterial
A32: 21 | B32: KENMORE AVE | C32: N | D32: KENMORE | E32: AVE | F32: N | G32: 5800 | H32: 5801 | I32: W ARDMORE AVE | J32: 5928 | K32: 5929 | L32: W THORNDALE AVE | M32: 4 | N32: BIKE LANE | O32: BIKE LANE | P32: MAINTAIN | R32: BIKE PRGM 14 | S32: 2014 | T32: 6 | W32: 0 | X32: 0 | Z32: 2014 | AA32: 0 | AB32: 0.18996178 | AC32: 0.18996178 | AE32: Y | AF32: N | AG32: N | AL32: 0 | AM32: 1 | AN32: 0 | AO32: 0 | AP32: 0 | AQ32: 0 | AR32: 0 | AS32: 0 | AT32: =SUM(AM32:AS32) -> 1 | AU32: 43335 | AV32: JP | AX32: 3 | AY32: Neighborhood | AZ32: 20
A33: 22 | B33: 83RD ST | C33: E | D33: 83RD | E33: ST | G33: 3132 | H33: 3133 | I33: S SOUTH SHORE DR | J33: 3358 | K33: 3359 | L33: S GREEN BAY AVE | M33: 3 | N33: BIKE LANE | O33: BIKE LANE | P33: NEW | Q33: 2011-9 | R33: MENU RESURFACING | S33: 2011 | T33: 6 | U33: RESURFACED | W33: 0 | X33: 0 | Z33: 2011 | AA33: 2011 | AB33: 0.31073508 | AC33: 0.62147016 | AE33: N | AL33: 0 | AM33: 0 | AN33: 0 | AO33: 0 | AP33: 1 | AQ33: 0 | AR33: 0 | AS33: 0 | AT33: =SUM(AM33:AS33) -> 1 | AU33: 43335 | AV33: JP | AX33: 2 | AY33: Arterial
A34: 23 | B34: DESPLAINES ST | C34: S | D34: DESPLAINES | E34: ST | F34: S | G34: 525 | H34: 524 | I34: W HARRISON ST | J34: 1 | K34: 2 | L34: W MADISON ST | M34: 4 | N34: PROTECTED BIKE LANE | O34: PROTECTED BIKE LANE | P34: NEW | Q34: 2012-12 | R34: BIKE PRGM 12 | S34: 2012 | T34: 11 | U34: ROAD DIET | W34: 0 | X34: 0 | Z34: 2012 | AA34: 0 | AB34: 0.51544828 | AC34: 0.51544828 | AE34: Y | AF34: S | AG34: N | AH34: N | AI34: POST | AJ34: - | AK34: - | AL34: 0 | AM34: 0 | AN34: 0 | AO34: 0 | AP34: 0 | AQ34: 0 | AR34: 0 | AS34: 1 | AT34: =SUM(AM34:AS34) -> 1 | AU34: 10.25.2022 | AV34: JP | AW34: Y | AX34: 1 | AY34: Arterial
A35: 24 | B35: CLARK ST | C35: N | D35: CLARK | E35: ST | G35: 1000 | H35: 1001 | I35: W OAK ST | J35: 1556 | K35: 1557 | L35: W NORTH AVE | M35: 3 | N35: BUFFERED BIKE LANE | O35: BUFFERED BIKE LANE | P35: NEW | Q35: 2012-8 | R35: AR 11 | S35: 2012 | T35: 8 | U35: RESURFACED | W35: 0 | X35: 0 | Z35: 2012 | AA35: 2012 | AB35: 0.73372982 | AC35: 1.4674596 | AE35: N | AL35: 0 | AM35: 0 | AN35: 0 | AO35: 0 | AP35: 0 | AQ35: 0 | AR35: 0 | AS35: 1 | AT35: =SUM(AM35:AS35) -> 1 | AU35: 43336 | AV35: JP | AW35: N | AX35: 2 | AY35: Arterial
A36: 25 | B36: BERTEAU AVE | C36: W | D36: BERTEAU | E36: AVE | G36: 1923 | H36: 1924 | I36: N DAMEN AVE | J36: 1600 | K36: 1601 | L36: N ASHLAND AVE | M36: 4 | N36: NEIGHBORHOOD GREENWAY | O36: SHARED-LANE | P36: NEW | Q36: 2013-2 | R36: MENU STRIPING | S36: 2013 | T36: 10 | W36: 0 | X36: 0 | Z36: 2013 | AA36: 0 | AB36: 0.50047928 | AC36: 1.0009586 | AD36: BERTEAU GREENWAY | AE36: N | AL36: 0 | AM36: 1 | AN36: 0 | AO36: 0 | AP36: 0 | AQ36: 0 | AR36: 0 | AS36: 0 | AT36: =SUM(AM36:AS36) -> 1 | AU36: 43336 | AV36: JP | AX36: 3 | AY36: Neighborhood
A37: 26 | B37: SOUTH CHICAGO AVE | C37: S | D37: SOUTH CHICAGO | E37: AVE | G37: 9379 | H37: 9386 | I37: S BALTIMORE AVE | J37: 7901 | K37: 7900 | L37: E 79TH ST | M37: 3 | N37: BUFFERED BIKE LANE | O37: BUFFERED BIKE LANE | P37: UPGRADE | Q37: 1996-9 | R37: AR 11 | S37: 2012 | T37: 6 | U37: ROAD DIET; RESURFACED | W37: 0 | X37: 0 | Z37: 2012 | AA37: 2012 | AB37: 2.6692262 | AC37: 5.3384525 | AE37: N | AL37: 0 | AM37: 0 | AN37: 0 | AO37: 0 | AP37: 1 | AQ37: 0 | AR37: 0 | AS37: 0 | AT37: =SUM(AM37:AS37) -> 1 | AU37: 43336 | AV37: JP | AW37: N | AX37: 2 | AY37: Arterial
A38: 27 | B38: WELLS ST | C38: N | D38: WELLS | E38: ST | G38: 800 | H38: 801 | I38: W CHICAGO AVE | J38: 1600 | K38: 1601 | L38: W NORTH AVE | M38: 4 | N38: BUFFERED BIKE LANE | O38: BUFFERED BIKE LANE | P38: MAINTAIN | Q38: 1993-4 | R38: AR 12 | S38: 2013 | T38: 7 | U38: RESURFACED | V38: MAINTENANCE 2020 | W38: 2020 | X38: 0 | Z38: 2020 | AA38: 2013 | AB38: 1.0056321 | AC38: 2.0112643 | AE38: N | AL38: 0 | AM38: 0 | AN38: 0 | AO38: 0 | AP38: 0 | AQ38: 0 | AR38: 0 | AS38: 1 | AT38: =SUM(AM38:AS38) -> 1 | AU38: 08.28.2020 | AV38: JP | AW38: N | AX38: 2 | AY38: Arterial
A39: 28 | B39: MILWAUKEE AVE | C39: N | D39: MILWAUKEE | E39: AVE | G39: 5100 | H39: 5100 | I39: N CARMEN AVE | J39: 6131 | K39: 6124 | L39: N HYACINTH ST | M39: 3 | N39: BUFFERED BIKE LANE | O39: BUFFERED BIKE LANE | P39: UPGRADE | Q39: 2011-28 | R39: AR 14 | S39: 2015 | T39: 7 | U39: RESURFACED | W39: 0 | X39: 0 | Z39: 2015 | AA39: 2015 | AB39: 1.6753159 | AC39: 3.3506317 | AE39: N | AL39: 0 | AM39: 0 | AN39: 1 | AO39: 0 | AP39: 0 | AQ39: 0 | AR39: 0 | AS39: 0 | AT39: =SUM(AM39:AS39) -> 1 | AU39: 43336 | AV39: JP | AW39: N | AX39: 2 | AY39: Arterial
A40: 29 | B40: GRAND AVE | C40: W | D40: GRAND | E40: AVE | F40: W | G40: 500 | H40: 501 | I40: N DEARBORN ST | J40: 520 | K40: 521 | L40: N STATE ST | M40: 3 | N40: BUFFERED BIKE LANE | O40: BUFFERED BIKE LANE | P40: MAINTAIN | Q40: 2011-20 | R40: BIKE PRGM 14 | S40: 2014 | T40: 9 | V40: MAINTENANCE 2020 | W40: 2020 | X40: 0 | Z40: 2020 | AA40: 0 | AB40: 0.081661266 | AC40: 0.081661266 | AE40: Y | AF40: W | AG40: N | AL40: 0 | AM40: 0 | AN40: 0 | AO40: 0 | AP40: 0 | AQ40: 0 | AR40: 0 | AS40: 1 | AT40: =SUM(AM40:AS40) -> 1 | AU40: 08.28.2020 | AV40: JP | AW40: N | AX40: 2 | AY40: Arterial
A41: 30 | B41: MILWAUKEE AVE | C41: N | D41: MILWAUKEE | E41: AVE | G41: 1600 | H41: 1601 | I41: W NORTH AVE | J41: 1764 | K41: 1769 | L41: N LEAVITT ST | M41: 3 | N41: BIKE LANE | O41: DASHED BIKE LANE | P41: UPGRADE | Q41: 2005-9 | R41: BIKE PRGM 17 | S41: 2017 | T41: 9 | U41: DASHED BIKE LANE FOR MAJORITY | W41: 0 | X41: 0 | Z41: 2017 | AA41: 2005 | AB41: 0.41450981 | AC41: 0.82901961 | AE41: N | AL41: 0 | AM41: 0 | AN41: 0 | AO41: 0 | AP41: 0 | AQ41: 0 | AR41: 0 | AS41: 1 | AT41: =SUM(AM41:AS41) -> 1 | AU41: 43336 | AV41: JP | AX41: 2 | AY41: Arterial | AZ41: 20
A42: 31 | B42: CALIFORNIA AVE | C42: N | D42: CALIFORNIA | E42: AVE | G42: 3600 | H42: 3601 | I42: W ADDISON ST | J42: 4401 | K42: 4400 | L42: N MONTROSE AVE | M42: 3 | N42: SHARED-LANE | O42: SHARED-LANE | P42: NEW | Q42: 2011-12 | R42: CMAQ 2009 | S42: 2011 | T42: 9 | W42: 0 | X42: 0 | Z42: 2011 | AA42: 0 | AB42: 1.0057464 | AC42: 2.0114928 | AE42: N | AL42: 0 | AM42: 0 | AN42: 1 | AO42: 0 | AP42: 0 | AQ42: 0 | AR42: 0 | AS42: 0 | AT42: =SUM(AM42:AS42) -> 1 | AU42: 43335 | AV42: JP | AX42: 2 | AY42: Arterial
A43: 32 | B43: JACKSON BLVD | C43: W | D43: JACKSON | E43: BLVD | G43: 2363 | H43: 2358 | I43: S WESTERN AVE | J43: 2301 | K43: 2300 | L43: S OAKLEY BLVD | M43: 4 | N43: BUFFERED BIKE LANE | O43: BUFFERED BIKE LANE | P43: NEW | Q43: 2011-22 | R43: TERM 11 | S43: 2011 | T43: 10 | U43: WESTBOUND - BIKE LANE | W43: 0 | X43: 0 | Z43: 2011 | AA43: 2011 | AB43: 0.12756244 | AC43: 0.25512489 | AE43: N | AL43: 0 | AM43: 0 | AN43: 0 | AO43: 0 | AP43: 0 | AQ43: 0 | AR43: 0 | AS43: 1 | AT43: =SUM(AM43:AS43) -> 1 | AU43: 43332 | AV43: JP | AW43: N | AX43: 2 | AY43: Arterial
A44: 33 | B44: JACKSON BLVD | C44: W | D44: JACKSON | E44: BLVD | G44: 2057 | H44: 2058 | I44: S HOYNE AVE | J44: 2001 | K44: 2000 | L44: S DAMEN AVE | M44: 4 | N44: BUFFERED BIKE LANE | O44: BUFFERED BIKE LANE | P44: NEW | Q44: 2011-22 | R44: TERM 11 | S44: 2011 | T44: 10 | U44: WESTBOUND - BIKE LANE | W44: 0 | X44: 0 | Z44: 2011 | AA44: 2011 | AB44: 0.12753278 | AC44: 0.25506556 | AE44: N | AL44: 0 | AM44: 0 | AN44: 0 | AO44: 0 | AP44: 0 | AQ44: 0 | AR44: 0 | AS44: 1 | AT44: =SUM(AM44:AS44) -> 1 | AU44: 43332 | AV44: JP | AW44: N | AX44: 2 | AY44: Arterial
...

Sheet Equity
A1: Equity Dashboard
A2: CDOT Bike Program
B4: North Side | D4: West Side | E4: South Side | H4: Central
B5: 1 | C5: 2 | D5: 3 | E5: 6 | F5: 4 | G5: 5 | H5: 7 | R5: 3-B Community Sub-District moved from West to Central
B6: N | C6: NW | D6: W | E6: S | F6: SW | G6: FS | H6: C | I6: TOTAL | L6: North | M6: West | N6: South | O6: Central | P6: TOTAL
A7: Facilities by Geography | I7: Centerline Miles | K7: Facilities by Geography | P7: Centerline Miles
A8: Protected Bike Lanes | B8: {=SUMPRODUCT(--(Network!$N$11:$N$1010=$R8),Network!$AB$11:$AB$1010,Network!AM$11:AM$1010)} -> 2.2278947 | C8: {=SUMPRODUCT(--(Network!$N$11:$N$1010=$R8),Network!$AB$11:$AB$1010,Network!AN$11:AN$1010)} -> 2.9493142 | D8: {=SUMPRODUCT(--(Network!$N$11:$N$1010=$R8),Network!$AB$11:$AB$1010,Network!AO$11:AO$1010)} -> 8.9760821 | E8: {=SUMPRODUCT(--(Network!$N$11:$N$1010=$R8),Network!$AB$11:$AB$1010,Network!AP$11:AP$1010)} -> 2.8572781 | F8: {=SUMPRODUCT(--(Network!$N$11:$N$1010=$R8),Network!$AB$11:$AB$1010,Network!AQ$11:AQ$1010)} -> 0.85219917 | G8: {=SUMPRODUCT(--(Network!$N$11:$N$1010=$R8),Network!$AB$11:$AB$1010,Network!AR$11:AR$1010)} -> 4.8739501 | H8: {=SUMPRODUCT(--(Network!$N$11:$N$1010=$R8),Network!$AB$11:$AB$1010,Network!AS$11:AS$1010)} -> 15.771943 | I8: =SUM(B8:H8) -> 38.508661 | K8: Protected Bike Lanes | L8: =SUM(B8:C8) -> 5.1772089 | M8: =D8 -> 8.9760821 | N8: =SUM(E8:G8) -> 8.5834274 | O8: =H8 -> 15.771943 | P8: =SUM(L8:O8) -> 38.508661 | R8: PROTECTED BIKE LANE
A9: Buffered Bike Lanes | B9: {=SUMPRODUCT(--(Network!$N$11:$N$1010=$R9),Network!$AB$11:$AB$1010,Network!AM$11:AM$1010)} -> 8.0785891 | C9: {=SUMPRODUCT(--(Network!$N$11:$N$1010=$R9),Network!$AB$11:$AB$1010,Network!AN$11:AN$1010)} -> 18.263911 | D9: {=SUMPRODUCT(--(Network!$N$11:$N$1010=$R9),Network!$AB$11:$AB$1010,Network!AO$11:AO$1010)} -> 13.229945 | E9: {=SUMPRODUCT(--(Network!$N$11:$N$1010=$R9),Network!$AB$11:$AB$1010,Network!AP$11:AP$1010)} -> 23.441441 | F9: {=SUMPRODUCT(--(Network!$N$11:$N$1010=$R9),Network!$AB$11:$AB$1010,Network!AQ$11:AQ$1010)} -> 11.645923 | G9: {=SUMPRODUCT(--(Network!$N$11:$N$1010=$R9),Network!$AB$11:$AB$1010,Network!AR$11:AR$1010)} -> 15.303757 | H9: {=SUMPRODUCT(--(Network!$N$11:$N$1010=$R9),Network!$AB$11:$AB$1010,Network!AS$11:AS$1010)} -> 25.611029 | I9: =SUM(B9:H9) -> 115.5746 | K9: Buffered Bike Lanes | L9: =SUM(B9:C9) -> 26.3425 | M9: =D9 -> 13.229945 | N9: =SUM(E9:G9) -> 50.391121 | O9: =H9 -> 25.611029 | P9: =SUM(L9:O9) -> 115.5746 | R9: BUFFERED BIKE LANE
A10: Bike Lanes | B10: {=SUMPRODUCT(--(Network!$N$11:$N$1010=$R10),Network!$AB$11:$AB$1010,Network!AM$11:AM$1010)} -> 29.101527 | C10: {=SUMPRODUCT(--(Network!$N$11:$N$1010=$R10),Network!$AB$11:$AB$1010,Network!AN$11:AN$1010)} -> 25.438934 | D10: {=SUMPRODUCT(--(Network!$N$11:$N$1010=$R10),Network!$AB$11:$AB$1010,Network!AO$11:AO$1010)} -> 14.215057 | E10: {=SUMPRODUCT(--(Network!$N$11:$N$1010=$R10),Network!$AB$11:$AB$1010,Network!AP$11:AP$1010)} -> 13.26998 | F10: {=SUMPRODUCT(--(Network!$N$11:$N$1010=$R10),Network!$AB$11:$AB$1010,Network!AQ$11:AQ$1010)} -> 7.2915513 | G10: {=SUMPRODUCT(--(Network!$N$11:$N$1010=$R10),Network!$AB$11:$AB$1010,Network!AR$11:AR$1010)} -> 13.993172 | H10: {=SUMPRODUCT(--(Network!$N$11:$N$1010=$R10),Network!$AB$11:$AB$1010,Network!AS$11:AS$1010)} -> 21.782756 | I10: =SUM(B10:H10) -> 125.09298 | K10: Bike Lanes | L10: =SUM(B10:C10) -> 54.540461 | M10: =D10 -> 14.215057 | N10: =SUM(E10:G10) -> 34.554704 | O10: =H10 -> 21.782756 | P10: =SUM(L10:O10) -> 125.09298 | R10: BIKE LANE
A11: Neighborhood Greenways | B11: {=SUMPRODUCT(--(Network!$N$11:$N$1010=$R11),Network!$AB$11:$AB$1010,Network!AM$11:AM$1010)} -> 13.89704 | C11: {=SUMPRODUCT(--(Network!$N$11:$N$1010=$R11),Network!$AB$11:$AB$1010,Network!AN$11:AN$1010)} -> 8.4924731 | D11: {=SUMPRODUCT(--(Network!$N$11:$N$1010=$R11),Network!$AB$11:$AB$1010,Network!AO$11:AO$1010)} -> 8.6537416 | E11: {=SUMPRODUCT(--(Network!$N$11:$N$1010=$R11),Network!$AB$11:$AB$1010,Network!AP$11:AP$1010)} -> 0 | F11: {=SUMPRODUCT(--(Network!$N$11:$N$1010=$R11),Network!$AB$11:$AB$1010,Network!AQ$11:AQ$1010)} -> 0 | G11: {=SUMPRODUCT(--(Network!$N$11:$N$1010=$R11),Network!$AB$11:$AB$1010,Network!AR$11:AR$1010)} -> 3.5877711 | H11: {=SUMPRODUCT(--(Network!$N$11:$N$1010=$R11),Network!$AB$11:$AB$1010,Network!AS$11:AS$1010)} -> 3.2810998 | I11: =SUM(B11:H11) -> 37.912126 | K11: Neighborhood Greenways | L11: =SUM(B11:C11) -> 22.389513 | M11: =D11 -> 8.6537416 | N11: =SUM(E11:G11) -> 3.5877711 | O11: =H11 -> 3.2810998 | P11: =SUM(L11:O11) -> 37.912126 | R11: NEIGHBORHOOD GREENWAY
A12: Marked Shared Lanes | B12: {=SUMPRODUCT(--(Network!$N$11:$N$1010=$R12),Network!$AB$11:$AB$1010,Network!AM$11:AM$1010)} -> 12.136764 | C12: {=SUMPRODUCT(--(Network!$N$11:$N$1010=$R12),Network!$AB$11:$AB$1010,Network!AN$11:AN$1010)} -> 8.8243776 | D12: {=SUMPRODUCT(--(Network!$N$11:$N$1010=$R12),Network!$AB$11:$AB$1010,Network!AO$11:AO$1010)} -> 3.4280644 | E12: {=SUMPRODUCT(--(Network!$N$11:$N$1010=$R12),Network!$AB$11:$AB$1010,Network!AP$11:AP$1010)} -> 5.7598033 | F12: {=SUMPRODUCT(--(Network!$N$11:$N$1010=$R12),Network!$AB$11:$AB$1010,Network!AQ$11:AQ$1010)} -> 6.5614027 | G12: {=SUMPRODUCT(--(Network!$N$11:$N$1010=$R12),Network!$AB$11:$AB$1010,Network!AR$11:AR$1010)} -> 7.99871 | H12: {=SUMPRODUCT(--(Network!$N$11:$N$1010=$R12),Network!$AB$11:$AB$1010,Network!AS$11:AS$1010)} -> 5.2765018 | I12: =SUM(B12:H12) -> 49.985623 | K12: Marked Shared Lanes | L12: =SUM(B12:C12) -> 20.961141 | M12: =D12 -> 3.4280644 | N12: =SUM(E12:G12) -> 20.319916 | O12: =H12 -> 5.2765018 | P12: =SUM(L12:O12) -> 49.985623 | R12: SHARED-LANE
A13: TOTAL | B13: =SUM(B8:B12) -> 65.441814 | C13: =SUM(C8:C12) -> 63.96901 | D13: =SUM(D8:D12) -> 48.50289 | E13: =SUM(E8:E12) -> 45.328503 | F13: =SUM(F8:F12) -> 26.351077 | G13: =SUM(G8:G12) -> 45.75736 | H13: =SUM(H8:H12) -> 71.723329 | I13: =SUM(I8:I12) -> 367.07398 | K13: TOTAL | L13: =SUM(L8:L12) -> 129.41082 | M13: =SUM(M8:M12) -> 48.50289 | N13: =SUM(N8:N12) -> 117.43694 | O13: =SUM(O8:O12) -> 71.723329 | P13: =SUM(P8:P12) -> 367.07398
A15: all but Shared Lanes | B15: =SUM(B8:B11) -> 53.305051 | C15: =SUM(C8:C11) -> 55.144633 | D15: =SUM(D8:D11) -> 45.074825 | E15: =SUM(E8:E11) -> 39.5687 | F15: =SUM(F8:F11) -> 19.789674 | G15: =SUM(G8:G11) -> 37.75865 | H15: =SUM(H8:H11) -> 66.446827 | I15: =SUM(I8:I11) -> 317.08836 | K15: all but Shared Lanes | L15: =SUM(L8:L11) -> 108.44968 | M15: =SUM(M8:M11) -> 45.074825 | N15: =SUM(N8:N11) -> 97.117023 | O15: =SUM(O8:O11) -> 66.446827 | P15: =SUM(P8:P11) -> 317.08836
A18: Share of Facilities by Geography | K18: Share of Facilities by Geography
A19: Protected Bike Lanes | B19: =B8/$I8 -> 0.057854379 | C19: =C8/$I8 -> 0.076588334 | D19: =D8/$I8 -> 0.23309255 | E19: =E8/$I8 -> 0.074198324 | F19: =F8/$I8 -> 0.022130065 | G19: =G8/$I8 -> 0.12656763 | H19: =H8/$I8 -> 0.40956871 | I19: =I8/$I8 -> 1 | K19: Protected Bike Lanes | L19: =L8/$P8 -> 0.13444271 | M19: =M8/$P8 -> 0.23309255 | N19: =N8/$P8 -> 0.22289602 | O19: =O8/$P8 -> 0.40956871 | P19: =P8/$P8 -> 1 | R19: PROTECTED BIKE LANE
A20: Buffered Bike Lanes | B20: =B9/$I9 -> 0.06989935 | C20: =C9/$I9 -> 0.15802704 | D20: =D9/$I9 -> 0.11447105 | E20: =E9/$I9 -> 0.20282521 | F20: =F9/$I9 -> 0.10076543 | G20: =G9/$I9 -> 0.13241454 | H20: =H9/$I9 -> 0.22159739 | I20: =I9/$I9 -> 1 | K20: Buffered Bike Lanes | L20: =L9/$P9 -> 0.22792639 | M20: =M9/$P9 -> 0.11447105 | N20: =N9/$P9 -> 0.43600517 | O20: =O9/$P9 -> 0.22159739 | P20: =P9/$P9 -> 1 | R20: BUFFERED BIKE LANE
A21: Bike Lanes | B21: =B10/$I10 -> 0.23263918 | C21: =C10/$I10 -> 0.20336021 | D21: =D10/$I10 -> 0.11363593 | E21: =E10/$I10 -> 0.10608094 | F21: =F10/$I10 -> 0.058289054 | G21: =G10/$I10 -> 0.11186217 | H21: =H10/$I10 -> 0.17413252 | I21: =I10/$I10 -> 1 | K21: Bike Lanes | L21: =L10/$P10 -> 0.43599939 | M21: =M10/$P10 -> 0.11363593 | N21: =N10/$P10 -> 0.27623216 | O21: =O10/$P10 -> 0.17413252 | P21: =P10/$P10 -> 1 | R21: BIKE LANE
A22: Neighborhood Greenways | B22: =B11/$I11 -> 0.36655924 | C22: =C11/$I11 -> 0.22400414 | D22: =D11/$I11 -> 0.22825789 | E22: =E11/$I11 -> 0 | F22: =F11/$I11 -> 0 | G22: =G11/$I11 -> 0.094633868 | H22: =H11/$I11 -> 0.086544864 | I22: =I11/$I11 -> 1 | K22: Neighborhood Greenways | L22: =L11/$P11 -> 0.59056338 | M22: =M11/$P11 -> 0.22825789 | N22: =N11/$P11 -> 0.094633868 | O22: =O11/$P11 -> 0.086544864 | P22: =P11/$P11 -> 1 | R22: NEIGHBORHOOD GREENWAY
A23: Marked Shared Lanes | B23: =B12/$I12 -> 0.24280509 | C23: =C12/$I12 -> 0.17653831 | D23: =D12/$I12 -> 0.068581007 | E23: =E12/$I12 -> 0.1152292 | F23: =F12/$I12 -> 0.1312658 | G23: =G12/$I12 -> 0.16002021 | H23: =H12/$I12 -> 0.10556039 | I23: =I12/$I12 -> 1 | K23: Marked Shared Lanes | L23: =L12/$P12 -> 0.4193434 | M23: =M12/$P12 -> 0.068581007 | N23: =N12/$P12 -> 0.40651521 | O23: =O12/$P12 -> 0.10556039 | P23: =P12/$P12 -> 1 | R23: SHARED-LANE
A24: TOTAL | B24: =B13/$I13 -> 0.17827963 | C24: =C13/$I13 -> 0.17426735 | D24: =D13/$I13 -> 0.13213383 | E24: =E13/$I13 -> 0.12348601 | F24: =F13/$I13 -> 0.071786827 | G24: =G13/$I13 -> 0.12465433 | H24: =H13/$I13 -> 0.19539203 | I24: =I13/$I13 -> 1 | K24: TOTAL | L24: =L13/$P13 -> 0.35254698 | M24: =M13/$P13 -> 0.13213383 | N24: =N13/$P13 -> 0.31992717 | O24: =O13/$P13 -> 0.19539203 | P24: =P13/$P13 -> 1
A26: all but Shared Lanes | B26: =B15/$I15 -> 0.16810788 | C26: =C15/$I15 -> 0.17390936 | D26: =D15/$I15 -> 0.14215225 | E26: =E15/$I15 -> 0.12478761 | F26: =F15/$I15 -> 0.062410597 | G26: =G15/$I15 -> 0.11907927 | H26: =H15/$I15 -> 0.20955303 | I26: =I15/$I15 -> 1 | K26: all but Shared Lanes | L26: =L15/$P15 -> 0.34201723 | M26: =M15/$P15 -> 0.14215225 | N26: =N15/$P15 -> 0.30627748 | O26: =O15/$P15 -> 0.20955303 | P26: =P15/$P15 -> 1
A29: Census | I29: Source: 2016 ACS 5-Year (Updated 8/27/2018) | K29: Census | P29: Source: 2016 ACS 5-Year (Updated 8/27/2018)
A30: Area | B30: =SUMIFS(Geographies!$G$6:$G$809,Geographies!$J$6:$J$809,B$5) -> 20.344508 | C30: =SUMIFS(Geographies!$G$6:$G$809,Geographies!$J$6:$J$809,C$5) -> 51.254445 | D30: =SUMIFS(Geographies!$G$6:$G$809,Geographies!$J$6:$J$809,D$5) -> 21.787325 | E30: =SUMIFS(Geographies!$G$6:$G$809,Geographies!$J$6:$J$809,E$5) -> 28.346796 | F30: =SUMIFS(Geographies!$G$6:$G$809,Geographies!$J$6:$J$809,F$5) -> 40.776885 | G30: =SUMIFS(Geographies!$G$6:$G$809,Geographies!$J$6:$J$809,G$5) -> 49.084347 | H30: =SUMIFS(Geographies!$G$6:$G$809,Geographies!$J$6:$J$809,H$5) -> 19.337014 | I30: =SUM(B30:H30) -> 230.93132 | K30: Area | L30: =SUM(B30:C30) -> 71.598953 | M30: =D30 -> 21.787325 | N30: =SUM(E30:G30) -> 118.20803 | O30: =H30 -> 19.337014 | P30: =SUM(L30:O30) -> 230.93132
A31: Percentage | B31: =B30/$I$30 -> 0.088097655 | C31: =C30/$I$30 -> 0.2219467 | D31: =D30/$I$30 -> 0.094345476 | E31: =E30/$I$30 -> 0.1227499 | F31: =F30/$I$30 -> 0.17657581 | G31: =G30/$I$30 -> 0.21254954 | H31: =H30/$I$30 -> 0.083734912 | I31: =I30/$I$30 -> 1 | K31: Percentage | L31: =L30/$P$30 -> 0.31004436 | M31: =M30/$P$30 -> 0.094345476 | N31: =N30/$P$30 -> 0.51187525 | O31: =O30/$P$30 -> 0.083734912 | P31: =P30/$P$30 -> 1
A32: Population | B32: =SUMIFS(Geographies!$L$6:$L$809,Geographies!$J$6:$J$809,B$5) -> #VALUE! | C32: =SUMIFS(Geographies!$L$6:$L$809,Geographies!$J$6:$J$809,C$5) -> #VALUE! | D32: =SUMIFS(Geographies!$L$6:$L$809,Geographies!$J$6:$J$809,D$5) -> #VALUE! | E32: =SUMIFS(Geographies!$L$6:$L$809,Geographies!$J$6:$J$809,E$5) -> #VALUE! | F32: =SUMIFS(Geographies!$L$6:$L$809,Geographies!$J$6:$J$809,F$5) -> #VALUE! | G32: =SUMIFS(Geographies!$L$6:$L$809,Geographies!$J$6:$J$809,G$5) -> #VALUE! | H32: =SUMIFS(Geographies!$L$6:$L$809,Geographies!$J$6:$J$809,H$5) -> #VALUE! | I32: =SUM(B32:H32) -> #VALUE! | K32: Population | L32: =SUM(B32:C32) -> #VALUE! | M32: =D32 -> #VALUE! | N32: =SUM(E32:G32) -> #VALUE! | O32: =H32 -> #VALUE! | P32: =SUM(L32:O32) -> #VALUE!
A33: Percentage | B33: =B32/$I$32 -> #VALUE! | C33: =C32/$I$32 -> #VALUE! | D33: =D32/$I$32 -> #VALUE! | E33: =E32/$I$32 -> #VALUE! | F33: =F32/$I$32 -> #VALUE! | G33: =G32/$I$32 -> #VALUE! | H33: =H32/$I$32 -> #VALUE! | I33: =I32/$I$32 -> #VALUE! | K33: Percentage | L33: =L32/$P$32 -> #VALUE! | M33: =M32/$P$32 -> #VALUE! | N33: =N32/$P$32 -> #VALUE! | O33: =O32/$P$32 -> #VALUE! | P33: =P32/$P$32 -> #VALUE!
A34: Density | B34: =B32/B30 -> #VALUE! | C34: =C32/C30 -> #VALUE! | D34: =D32/D30 -> #VALUE! | E34: =E32/E30 -> #VALUE! | F34: =F32/F30 -> #VALUE! | G34: =G32/G30 -> #VALUE! | H34: =H32/H30 -> #VALUE! | I34: =I32/I30 -> #VALUE! | K34: Density | L34: =L32/L30 -> #VALUE! | M34: =M32/M30 -> #VALUE! | N34: =N32/N30 -> #VALUE! | O34: =O32/O30 -> #VALUE! | P34: =P32/P30 -> #VALUE!
A36: Automobile | B36: =SUMIFS(Geographies!$N$6:$N$809,Geographies!$J$6:$J$809,B$5) -> #VALUE! | C36: =SUMIFS(Geographies!$N$6:$N$809,Geographies!$J$6:$J$809,C$5) -> #VALUE! | D36: =SUMIFS(Geographies!$N$6:$N$809,Geographies!$J$6:$J$809,D$5) -> #VALUE! | E36: =SUMIFS(Geographies!$N$6:$N$809,Geographies!$J$6:$J$809,E$5) -> #VALUE! | F36: =SUMIFS(Geographies!$N$6:$N$809,Geographies!$J$6:$J$809,F$5) -> #VALUE! | G36: =SUMIFS(Geographies!$N$6:$N$809,Geographies!$J$6:$J$809,G$5) -> #VALUE! | H36: =SUMIFS(Geographies!$N$6:$N$809,Geographies!$J$6:$J$809,H$5) -> #VALUE! | I36: =SUM(B36:H36) -> #VALUE! | K36: Automobile | L36: =SUM(B36:C36) -> #VALUE! | M36: =D36 -> #VALUE! | N36: =SUM(E36:G36) -> #VALUE! | O36: =H36 -> #VALUE! | P36: =SUM(L36:O36) -> #VALUE!
A37: Transit | B37: =SUMIFS(Geographies!$O$6:$O$809,Geographies!$J$6:$J$809,B$5) -> #VALUE! | C37: =SUMIFS(Geographies!$O$6:$O$809,Geographies!$J$6:$J$809,C$5) -> #VALUE! | D37: =SUMIFS(Geographies!$O$6:$O$809,Geographies!$J$6:$J$809,D$5) -> #VALUE! | E37: =SUMIFS(Geographies!$O$6:$O$809,Geographies!$J$6:$J$809,E$5) -> #VALUE! | F37: =SUMIFS(Geographies!$O$6:$O$809,Geographies!$J$6:$J$809,F$5) -> #VALUE! | G37: =SUMIFS(Geographies!$O$6:$O$809,Geographies!$J$6:$J$809,G$5) -> #VALUE! | H37: =SUMIFS(Geographies!$O$6:$O$809,Geographies!$J$6:$J$809,H$5) -> #VALUE! | I37: =SUM(B37:H37) -> #VALUE! | K37: Transit | L37: =SUM(B37:C37) -> #VALUE! | M37: =D37 -> #VALUE! | N37: =SUM(E37:G37) -> #VALUE! | O37: =H37 -> #VALUE! | P37: =SUM(L37:O37) -> #VALUE!
A38: Taxi | B38: =SUMIFS(Geographies!$P$6:$P$809,Geographies!$J$6:$J$809,B$5) -> #VALUE! | C38: =SUMIFS(Geographies!$P$6:$P$809,Geographies!$J$6:$J$809,C$5) -> #VALUE! | D38: =SUMIFS(Geographies!$P$6:$P$809,Geographies!$J$6:$J$809,D$5) -> #VALUE! | E38: =SUMIFS(Geographies!$P$6:$P$809,Geographies!$J$6:$J$809,E$5) -> #VALUE! | F38: =SUMIFS(Geographies!$P$6:$P$809,Geographies!$J$6:$J$809,F$5) -> #VALUE! | G38: =SUMIFS(Geographies!$P$6:$P$809,Geographies!$J$6:$J$809,G$5) -> #VALUE! | H38: =SUMIFS(Geographies!$P$6:$P$809,Geographies!$J$6:$J$809,H$5) -> #VALUE! | I38: =SUM(B38:H38) -> #VALUE! | K38: Taxi | L38: =SUM(B38:C38) -> #VALUE! | M38: =D38 -> #VALUE! | N38: =SUM(E38:G38) -> #VALUE! | O38: =H38 -> #VALUE! | P38: =SUM(L38:O38) -> #VALUE!
A39: Bike | B39: =SUMIFS(Geographies!$Q$6:$Q$809,Geographies!$J$6:$J$809,B$5) -> #VALUE! | C39: =SUMIFS(Geographies!$Q$6:$Q$809,Geographies!$J$6:$J$809,C$5) -> #VALUE! | D39: =SUMIFS(Geographies!$Q$6:$Q$809,Geographies!$J$6:$J$809,D$5) -> #VALUE! | E39: =SUMIFS(Geographies!$Q$6:$Q$809,Geographies!$J$6:$J$809,E$5) -> #VALUE! | F39: =SUMIFS(Geographies!$Q$6:$Q$809,Geographies!$J$6:$J$809,F$5) -> #VALUE! | G39: =SUMIFS(Geographies!$Q$6:$Q$809,Geographies!$J$6:$J$809,G$5) -> #VALUE! | H39: =SUMIFS(Geographies!$Q$6:$Q$809,Geographies!$J$6:$J$809,H$5) -> #VALUE! | I39: =SUM(B39:H39) -> #VALUE! | K39: Bike | L39: =SUM(B39:C39) -> #VALUE! | M39: =D39 -> #VALUE! | N39: =SUM(E39:G39) -> #VALUE! | O39: =H39 -> #VALUE! | P39: =SUM(L39:O39) -> #VALUE!
A40: Walk | B40: =SUMIFS(Geographies!$R$6:$R$809,Geographies!$J$6:$J$809,B$5) -> #VALUE! | C40: =SUMIFS(Geographies!$R$6:$R$809,Geographies!$J$6:$J$809,C$5) -> #VALUE! | D40: =SUMIFS(Geographies!$R$6:$R$809,Geographies!$J$6:$J$809,D$5) -> #VALUE! | E40: =SUMIFS(Geographies!$R$6:$R$809,Geographies!$J$6:$J$809,E$5) -> #VALUE! | F40: =SUMIFS(Geographies!$R$6:$R$809,Geographies!$J$6:$J$809,F$5) -> #VALUE! | G40: =SUMIFS(Geographies!$R$6:$R$809,Geographies!$J$6:$J$809,G$5) -> #VALUE! | H40: =SUMIFS(Geographies!$R$6:$R$809,Geographies!$J$6:$J$809,H$5) -> #VALUE! | I40: =SUM(B40:H40) -> #VALUE! | K40: Walk | L40: =SUM(B40:C40) -> #VALUE! | M40: =D40 -> #VALUE! | N40: =SUM(E40:G40) -> #VALUE! | O40: =H40 -> #VALUE! | P40: =SUM(L40:O40) -> #VALUE!
A41: Other | B41: =SUMIFS(Geographies!$S$6:$S$809,Geographies!$J$6:$J$809,B$5) -> #VALUE! | C41: =SUMIFS(Geographies!$S$6:$S$809,Geographies!$J$6:$J$809,C$5) -> #VALUE! | D41: =SUMIFS(Geographies!$S$6:$S$809,Geographies!$J$6:$J$809,D$5) -> #VALUE! | E41: =SUMIFS(Geographies!$S$6:$S$809,Geographies!$J$6:$J$809,E$5) -> #VALUE! | F41: =SUMIFS(Geographies!$S$6:$S$809,Geographies!$J$6:$J$809,F$5) -> #VALUE! | G41: =SUMIFS(Geographies!$S$6:$S$809,Geographies!$J$6:$J$809,G$5) -> #VALUE! | H41: =SUMIFS(Geographies!$S$6:$S$809,Geographies!$J$6:$J$809,H$5) -> #VALUE! | I41: =SUM(B41:H41) -> #VALUE! | K41: Other | L41: =SUM(B41:C41) -> #VALUE! | M41: =D41 -> #VALUE! | N41: =SUM(E41:G41) -> #VALUE! | O41: =H41 -> #VALUE! | P41: =SUM(L41:O41) -> #VALUE!
A42: TOTAL COMMUTERS | B42: =SUMIFS(Geographies!$M$6:$M$809,Geographies!$J$6:$J$809,B$5) -> #VALUE! | C42: =SUMIFS(Geographies!$M$6:$M$809,Geographies!$J$6:$J$809,C$5) -> #VALUE! | D42: =SUMIFS(Geographies!$M$6:$M$809,Geographies!$J$6:$J$809,D$5) -> #VALUE! | E42: =SUMIFS(Geographies!$M$6:$M$809,Geographies!$J$6:$J$809,E$5) -> #VALUE! | F42: =SUMIFS(Geographies!$M$6:$M$809,Geographies!$J$6:$J$809,F$5) -> #VALUE! | G42: =SUMIFS(Geographies!$M$6:$M$809,Geographies!$J$6:$J$809,G$5) -> #VALUE! | H42: =SUMIFS(Geographies!$M$6:$M$809,Geographies!$J$6:$J$809,H$5) -> #VALUE! | I42: =SUM(B42:H42) -> #VALUE! | K42: TOTAL COMMUTERS | L42: =SUM(B42:C42) -> #VALUE! | M42: =D42 -> #VALUE! | N42: =SUM(E42:G42) -> #VALUE! | O42: =H42 -> #VALUE! | P42: =SUM(L42:O42) -> #VALUE!
A44: Automobile | B44: =B36/B$42 -> #VALUE! | C44: =C36/C$42 -> #VALUE! | D44: =D36/D$42 -> #VALUE! | E44: =E36/E$42 -> #VALUE! | F44: =F36/F$42 -> #VALUE! | G44: =G36/G$42 -> #VALUE! | H44: =H36/H$42 -> #VALUE! | I44: =I36/I$42 -> #VALUE! | K44: Automobile | L44: =L36/L$42 -> #VALUE! | M44: =M36/M$42 -> #VALUE! | N44: =N36/N$42 -> #VALUE! | O44: =O36/O$42 -> #VALUE! | P44: =P36/P$42 -> #VALUE!
A45: Transit | B45: =B37/B$42 -> #VALUE! | C45: =C37/C$42 -> #VALUE! | D45: =D37/D$42 -> #VALUE! | E45: =E37/E$42 -> #VALUE! | F45: =F37/F$42 -> #VALUE! | G45: =G37/G$42 -> #VALUE! | H45: =H37/H$42 -> #VALUE! | I45: =I37/I$42 -> #VALUE! | K45: Transit | L45: =L37/L$42 -> #VALUE! | M45: =M37/M$42 -> #VALUE! | N45: =N37/N$42 -> #VALUE! | O45: =O37/O$42 -> #VALUE! | P45: =P37/P$42 -> #VALUE!
A46: Taxi | B46: =B38/B$42 -> #VALUE! | C46: =C38/C$42 -> #VALUE! | D46: =D38/D$42 -> #VALUE! | E46: =E38/E$42 -> #VALUE! | F46: =F38/F$42 -> #VALUE! | G46: =G38/G$42 -> #VALUE! | H46: =H38/H$42 -> #VALUE! | I46: =I38/I$42 -> #VALUE! | K46: Taxi | L46: =L38/L$42 -> #VALUE! | M46: =M38/M$42 -> #VALUE! | N46: =N38/N$42 -> #VALUE! | O46: =O38/O$42 -> #VALUE! | P46: =P38/P$42 -> #VALUE!
A47: Bike | B47: =B39/B$42 -> #VALUE! | C47: =C39/C$42 -> #VALUE! | D47: =D39/D$42 -> #VALUE! | E47: =E39/E$42 -> #VALUE! | F47: =F39/F$42 -> #VALUE! | G47: =G39/G$42 -> #VALUE! | H47: =H39/H$42 -> #VALUE! | I47: =I39/I$42 -> #VALUE! | K47: Bike | L47: =L39/L$42 -> #VALUE! | M47: =M39/M$42 -> #VALUE! | N47: =N39/N$42 -> #VALUE! | O47: =O39/O$42 -> #VALUE! | P47: =P39/P$42 -> #VALUE!
A48: Walk | B48: =B40/B$42 -> #VALUE! | C48: =C40/C$42 -> #VALUE! | D48: =D40/D$42 -> #VALUE! | E48: =E40/E$42 -> #VALUE! | F48: =F40/F$42 -> #VALUE! | G48: =G40/G$42 -> #VALUE! | H48: =H40/H$42 -> #VALUE! | I48: =I40/I$42 -> #VALUE! | K48: Walk | L48: =L40/L$42 -> #VALUE! | M48: =M40/M$42 -> #VALUE! | N48: =N40/N$42 -> #VALUE! | O48: =O40/O$42 -> #VALUE! | P48: =P40/P$42 -> #VALUE!
A49: Other | B49: =B41/B$42 -> #VALUE! | C49: =C41/C$42 -> #VALUE! | D49: =D41/D$42 -> #VALUE! | E49: =E41/E$42 -> #VALUE! | F49: =F41/F$42 -> #VALUE! | G49: =G41/G$42 -> #VALUE! | H49: =H41/H$42 -> #VALUE! | I49: =I41/I$42 -> #VALUE! | K49: Other | L49: =L41/L$42 -> #VALUE! | M49: =M41/M$42 -> #VALUE! | N49: =N41/N$42 -> #VALUE! | O49: =O41/O$42 -> #VALUE! | P49: =P41/P$42 -> #VALUE!
...

Sheet Geographies
A1: Geographies
A2: for Equity Tracking
H3: Assign Community Area & Equity District | L3: 2020 ACS 5-Year B08301 | T3: Population within a 1/2 mile of
M4: B08301_001E | N4: B08301_002E | O4: B08301_010E | P4: B08301_016E | Q4: B08301_018E | R4: B08301_019E | T4: All Bikeways | V4: > MSL | X4: Low Stress | Z4: Low Stress & Trails
A5: CENSUS_TRACT | B5: CENSUS_TRACT_FULL | C5: TRACT_FIPS | D5: TRACT_CENSUS_YEAR | E5: Community Area | F5: SHAPE.AREA | G5: Sq Miles | H5: Area Name | I5: Group | J5: Region | K5: District | L5: Population | M5: Workers | N5: Automobile | O5: Transit | P5: Taxi | Q5: Bike | R5: Walk | S5: Other | T5: Sq Miles | U5: Population | V5: Sq Miles | W5: Population | X5: Sq Miles | Y5: Population | Z5: Sq Miles | AA5: Population
A6: 350400 | B6: 17031350400 | C6: 17031 | D6: 2010 | E6: 35 | F6: 2163073.4 | G6: 0.077589581 | H6: =_xlfn.IFNA( INDEX('Community Areas'!B$2:B$78,MATCH($E6,'Community Areas'!$A$2:$A$78,0)), "") -> DOUGLAS | I6: =_xlfn.IFNA( INDEX('Community Areas'!C$2:C$78,MATCH($E6,'Community Areas'!$A$2:$A$78,0)), "") -> 6-A | J6: =_xlfn.IFNA( INDEX('Community Areas'!D$2:D$78,MATCH($E6,'Community Areas'!$A$2:$A$78,0)), "") -> 6 | K6: =_xlfn.IFNA( INDEX('Community Areas'!E$2:E$78,MATCH($E6,'Community Areas'!$A$2:$A$78,0)), "") -> SOUTH | L6: =SUMIFS([1]ACSDT5Y2020.B08301_data_with_ov!AT$3:AT$1334,[1]ACSDT5Y2020.B08301_data_with_ov!$AS$3:$AS$1334,$B6) -> #VALUE! | M6: =SUMIFS([1]ACSDT5Y2020.B08301_data_with_ov!AU$3:AU$1334,[1]ACSDT5Y2020.B08301_data_with_ov!$AS$3:$AS$1334,$B6) -> #VALUE! | N6: =SUMIFS([1]ACSDT5Y2020.B08301_data_with_ov!AV$3:AV$1334,[1]ACSDT5Y2020.B08301_data_with_ov!$AS$3:$AS$1334,$B6) -> #VALUE! | O6: =SUMIFS([1]ACSDT5Y2020.B08301_data_with_ov!AW$3:AW$1334,[1]ACSDT5Y2020.B08301_data_with_ov!$AS$3:$AS$1334,$B6) -> #VALUE! | P6: =SUMIFS([1]ACSDT5Y2020.B08301_data_with_ov!AX$3:AX$1334,[1]ACSDT5Y2020.B08301_data_with_ov!$AS$3:$AS$1334,$B6) -> #VALUE! | Q6: =SUMIFS([1]ACSDT5Y2020.B08301_data_with_ov!AY$3:AY$1334,[1]ACSDT5Y2020.B08301_data_with_ov!$AS$3:$AS$1334,$B6) -> #VALUE! | R6: =SUMIFS([1]ACSDT5Y2020.B08301_data_with_ov!AZ$3:AZ$1334,[1]ACSDT5Y2020.B08301_data_with_ov!$AS$3:$AS$1334,$B6) -> #VALUE! | S6: =SUMIFS([1]ACSDT5Y2020.B08301_data_with_ov!BA$3:BA$1334,[1]ACSDT5Y2020.B08301_data_with_ov!$AS$3:$AS$1334,$B6) -> #VALUE! | T6: 0.07758958 | U6: =(T6/$G6)*$L6 -> #VALUE! | V6: 0.07758958 | W6: =(V6/$G6)*$L6 -> #VALUE! | X6: 0.07758958 | Y6: =(X6/$G6)*$L6 -> #VALUE! | Z6: 0.07758958 | AA6: =(Z6/$G6)*$L6 -> #VALUE!
A7: 839500 | B7: 17031839500 | C7: 17031 | D7: 2010 | E7: 35 | F7: 2825468.3 | G7: 0.10134973 | H7: =_xlfn.IFNA( INDEX('Community Areas'!B$2:B$78,MATCH($E7,'Community Areas'!$A$2:$A$78,0)), "") -> DOUGLAS | I7: =_xlfn.IFNA( INDEX('Community Areas'!C$2:C$78,MATCH($E7,'Community Areas'!$A$2:$A$78,0)), "") -> 6-A | J7: =_xlfn.IFNA( INDEX('Community Areas'!D$2:D$78,MATCH($E7,'Community Areas'!$A$2:$A$78,0)), "") -> 6 | K7: =_xlfn.IFNA( INDEX('Community Areas'!E$2:E$78,MATCH($E7,'Community Areas'!$A$2:$A$78,0)), "") -> SOUTH | L7: =SUMIFS([1]ACSDT5Y2020.B08301_data_with_ov!AT$3:AT$1334,[1]ACSDT5Y2020.B08301_data_with_ov!$AS$3:$AS$1334,$B7) -> #VALUE! | M7: =SUMIFS([1]ACSDT5Y2020.B08301_data_with_ov!AU$3:AU$1334,[1]ACSDT5Y2020.B08301_data_with_ov!$AS$3:$AS$1334,$B7) -> #VALUE! | N7: =SUMIFS([1]ACSDT5Y2020.B08301_data_with_ov!AV$3:AV$1334,[1]ACSDT5Y2020.B08301_data_with_ov!$AS$3:$AS$1334,$B7) -> #VALUE! | O7: =SUMIFS([1]ACSDT5Y2020.B08301_data_with_ov!AW$3:AW$1334,[1]ACSDT5Y2020.B08301_data_with_ov!$AS$3:$AS$1334,$B7) -> #VALUE! | P7: =SUMIFS([1]ACSDT5Y2020.B08301_data_with_ov!AX$3:AX$1334,[1]ACSDT5Y2020.B08301_data_with_ov!$AS$3:$AS$1334,$B7) -> #VALUE! | Q7: =SUMIFS([1]ACSDT5Y2020.B08301_data_with_ov!AY$3:AY$1334,[1]ACSDT5Y2020.B08301_data_with_ov!$AS$3:$AS$1334,$B7) -> #VALUE! | R7: =SUMIFS([1]ACSDT5Y2020.B08301_data_with_ov!AZ$3:AZ$1334,[1]ACSDT5Y2020.B08301_data_with_ov!$AS$3:$AS$1334,$B7) -> #VALUE! | S7: =SUMIFS([1]ACSDT5Y2020.B08301_data_with_ov!BA$3:BA$1334,[1]ACSDT5Y2020.B08301_data_with_ov!$AS$3:$AS$1334,$B7) -> #VALUE! | T7: 0.10134973 | U7: =(T7/$G7)*$L7 -> #VALUE! | V7: 0.10134973 | W7: =(V7/$G7)*$L7 -> #VALUE! | X7: 0.10134973 | Y7: =(X7/$G7)*$L7 -> #VALUE! | Z7: 0.10134973 | AA7: =(Z7/$G7)*$L7 -> #VALUE!
A8: 839600 | B8: 17031839600 | C8: 17031 | D8: 2010 | E8: 35 | F8: 3518755 | G8: 0.12621797 | H8: =_xlfn.IFNA( INDEX('Community Areas'!B$2:B$78,MATCH($E8,'Community Areas'!$A$2:$A$78,0)), "") -> DOUGLAS | I8: =_xlfn.IFNA( INDEX('Community Areas'!C$2:C$78,MATCH($E8,'Community Areas'!$A$2:$A$78,0)), "") -> 6-A | J8: =_xlfn.IFNA( INDEX('Community Areas'!D$2:D$78,MATCH($E8,'Community Areas'!$A$2:$A$78,0)), "") -> 6 | K8: =_xlfn.IFNA( INDEX('Community Areas'!E$2:E$78,MATCH($E8,'Community Areas'!$A$2:$A$78,0)), "") -> SOUTH | L8: =SUMIFS([1]ACSDT5Y2020.B08301_data_with_ov!AT$3:AT$1334,[1]ACSDT5Y2020.B08301_data_with_ov!$AS$3:$AS$1334,$B8) -> #VALUE! | M8: =SUMIFS([1]ACSDT5Y2020.B08301_data_with_ov!AU$3:AU$1334,[1]ACSDT5Y2020.B08301_data_with_ov!$AS$3:$AS$1334,$B8) -> #VALUE! | N8: =SUMIFS([1]ACSDT5Y2020.B08301_data_with_ov!AV$3:AV$1334,[1]ACSDT5Y2020.B08301_data_with_ov!$AS$3:$AS$1334,$B8) -> #VALUE! | O8: =SUMIFS([1]ACSDT5Y2020.B08301_data_with_ov!AW$3:AW$1334,[1]ACSDT5Y2020.B08301_data_with_ov!$AS$3:$AS$1334,$B8) -> #VALUE! | P8: =SUMIFS([1]ACSDT5Y2020.B08301_data_with_ov!AX$3:AX$1334,[1]ACSDT5Y2020.B08301_data_with_ov!$AS$3:$AS$1334,$B8) -> #VALUE! | Q8: =SUMIFS([1]ACSDT5Y2020.B08301_data_with_ov!AY$3:AY$1334,[1]ACSDT5Y2020.B08301_data_with_ov!$AS$3:$AS$1334,$B8) -> #VALUE! | R8: =SUMIFS([1]ACSDT5Y2020.B08301_data_with_ov!AZ$3:AZ$1334,[1]ACSDT5Y2020.B08301_data_with_ov!$AS$3:$AS$1334,$B8) -> #VALUE! | S8: =SUMIFS([1]ACSDT5Y2020.B08301_data_with_ov!BA$3:BA$1334,[1]ACSDT5Y2020.B08301_data_with_ov!$AS$3:$AS$1334,$B8) -> #VALUE! | T8: 0.12621797 | U8: =(T8/$G8)*$L8 -> #VALUE! | V8: 0.12621797 | W8: =(V8/$G8)*$L8 -> #VALUE! | X8: 0.12621797 | Y8: =(X8/$G8)*$L8 -> #VALUE! | Z8: 0.12621797 | AA8: =(Z8/$G8)*$L8 -> #VALUE!
A9: 842000 | B9: 17031842000 | C9: 17031 | D9: 2010 | E9: 35 | F9: 6328580.6 | G9: 0.22700659 | H9: =_xlfn.IFNA( INDEX('Community Areas'!B$2:B$78,MATCH($E9,'Community Areas'!$A$2:$A$78,0)), "") -> DOUGLAS | I9: =_xlfn.IFNA( INDEX('Community Areas'!C$2:C$78,MATCH($E9,'Community Areas'!$A$2:$A$78,0)), "") -> 6-A | J9: =_xlfn.IFNA( INDEX('Community Areas'!D$2:D$78,MATCH($E9,'Community Areas'!$A$2:$A$78,0)), "") -> 6 | K9: =_xlfn.IFNA( INDEX('Community Areas'!E$2:E$78,MATCH($E9,'Community Areas'!$A$2:$A$78,0)), "") -> SOUTH | L9: =SUMIFS([1]ACSDT5Y2020.B08301_data_with_ov!AT$3:AT$1334,[1]ACSDT5Y2020.B08301_data_with_ov!$AS$3:$AS$1334,$B9) -> #VALUE! | M9: =SUMIFS([1]ACSDT5Y2020.B08301_data_with_ov!AU$3:AU$1334,[1]ACSDT5Y2020.B08301_data_with_ov!$AS$3:$AS$1334,$B9) -> #VALUE! | N9: =SUMIFS([1]ACSDT5Y2020.B08301_data_with_ov!AV$3:AV$1334,[1]ACSDT5Y2020.B08301_data_with_ov!$AS$3:$AS$1334,$B9) -> #VALUE! | O9: =SUMIFS([1]ACSDT5Y2020.B08301_data_with_ov!AW$3:AW$1334,[1]ACSDT5Y2020.B08301_data_with_ov!$AS$3:$AS$1334,$B9) -> #VALUE! | P9: =SUMIFS([1]ACSDT5Y2020.B08301_data_with_ov!AX$3:AX$1334,[1]ACSDT5Y2020.B08301_data_with_ov!$AS$3:$AS$1334,$B9) -> #VALUE! | Q9: =SUMIFS([1]ACSDT5Y2020.B08301_data_with_ov!AY$3:AY$1334,[1]ACSDT5Y2020.B08301_data_with_ov!$AS$3:$AS$1334,$B9) -> #VALUE! | R9: =SUMIFS([1]ACSDT5Y2020.B08301_data_with_ov!AZ$3:AZ$1334,[1]ACSDT5Y2020.B08301_data_with_ov!$AS$3:$AS$1334,$B9) -> #VALUE! | S9: =SUMIFS([1]ACSDT5Y2020.B08301_data_with_ov!BA$3:BA$1334,[1]ACSDT5Y2020.B08301_data_with_ov!$AS$3:$AS$1334,$B9) -> #VALUE! | T9: 0.2270066 | U9: =(T9/$G9)*$L9 -> #VALUE! | V9: 0.2270066 | W9: =(V9/$G9)*$L9 -> #VALUE! | X9: 0.2270066 | Y9: =(X9/$G9)*$L9 -> #VALUE! | Z9: 0.2270066 | AA9: =(Z9/$G9)*$L9 -> #VALUE!
A10: 839200 | B10: 17031839200 | C10: 17031 | D10: 2010 | E10: 35 | F10: 7006617.4 | G10: 0.25132782 | H10: =_xlfn.IFNA( INDEX('Community Areas'!B$2:B$78,MATCH($E10,'Community Areas'!$A$2:$A$78,0)), "") -> DOUGLAS | I10: =_xlfn.IFNA( INDEX('Community Areas'!C$2:C$78,MATCH($E10,'Community Areas'!$A$2:$A$78,0)), "") -> 6-A | J10: =_xlfn.IFNA( INDEX('Community Areas'!D$2:D$78,MATCH($E10,'Community Areas'!$A$2:$A$78,0)), "") -> 6 | K10: =_xlfn.IFNA( INDEX('Community Areas'!E$2:E$78,MATCH($E10,'Community Areas'!$A$2:$A$78,0)), "") -> SOUTH | L10: =SUMIFS([1]ACSDT5Y2020.B08301_data_with_ov!AT$3:AT$1334,[1]ACSDT5Y2020.B08301_data_with_ov!$AS$3:$AS$1334,$B10) -> #VALUE! | M10: =SUMIFS([1]ACSDT5Y2020.B08301_data_with_ov!AU$3:AU$1334,[1]ACSDT5Y2020.B08301_data_with_ov!$AS$3:$AS$1334,$B10) -> #VALUE! | N10: =SUMIFS([1]ACSDT5Y2020.B08301_data_with_ov!AV$3:AV$1334,[1]ACSDT5Y2020.B08301_data_with_ov!$AS$3:$AS$1334,$B10) -> #VALUE! | O10: =SUMIFS([1]ACSDT5Y2020.B08301_data_with_ov!AW$3:AW$1334,[1]ACSDT5Y2020.B08301_data_with_ov!$AS$3:$AS$1334,$B10) -> #VALUE! | P10: =SUMIFS([1]ACSDT5Y2020.B08301_data_with_ov!AX$3:AX$1334,[1]ACSDT5Y2020.B08301_data_with_ov!$AS$3:$AS$1334,$B10) -> #VALUE! | Q10: =SUMIFS([1]ACSDT5Y2020.B08301_data_with_ov!AY$3:AY$1334,[1]ACSDT5Y2020.B08301_data_with_ov!$AS$3:$AS$1334,$B10) -> #VALUE! | R10: =SUMIFS([1]ACSDT5Y2020.B08301_data_with_ov!AZ$3:AZ$1334,[1]ACSDT5Y2020.B08301_data_with_ov!$AS$3:$AS$1334,$B10) -> #VALUE! | S10: =SUMIFS([1]ACSDT5Y2020.B08301_data_with_ov!BA$3:BA$1334,[1]ACSDT5Y2020.B08301_data_with_ov!$AS$3:$AS$1334,$B10) -> #VALUE! | T10: 0.25132782 | U10: =(T10/$G10)*$L10 -> #VALUE! | V10: 0.25132782 | W10: =(V10/$G10)*$L10 -> #VALUE! | X10: 0.25132782 | Y10: =(X10/$G10)*$L10 -> #VALUE! | Z10: 0.25132782 | AA10: =(Z10/$G10)*$L10 -> #VALUE!
A11: 351000 | B11: 17031351000 | C11: 17031 | D11: 2010 | E11: 35 | F11: 8900946.2 | G11: 0.31927751 | H11: =_xlfn.IFNA( INDEX('Community Areas'!B$2:B$78,MATCH($E11,'Community Areas'!$A$2:$A$78,0)), "") -> DOUGLAS | I11: =_xlfn.IFNA( INDEX('Community Areas'!C$2:C$78,MATCH($E11,'Community Areas'!$A$2:$A$78,0)), "") -> 6-A | J11: =_xlfn.IFNA( INDEX('Community Areas'!D$2:D$78,MATCH($E11,'Community Areas'!$A$2:$A$78,0)), "") -> 6 | K11: =_xlfn.IFNA( INDEX('Community Areas'!E$2:E$78,MATCH($E11,'Community Areas'!$A$2:$A$78,0)), "") -> SOUTH | L11: =SUMIFS([1]ACSDT5Y2020.B08301_data_with_ov!AT$3:AT$1334,[1]ACSDT5Y2020.B08301_data_with_ov!$AS$3:$AS$1334,$B11) -> #VALUE! | M11: =SUMIFS([1]ACSDT5Y2020.B08301_data_with_ov!AU$3:AU$1334,[1]ACSDT5Y2020.B08301_data_with_ov!$AS$3:$AS$1334,$B11) -> #VALUE! | N11: =SUMIFS([1]ACSDT5Y2020.B08301_data_with_ov!AV$3:AV$1334,[1]ACSDT5Y2020.B08301_data_with_ov!$AS$3:$AS$1334,$B11) -> #VALUE! | O11: =SUMIFS([1]ACSDT5Y2020.B08301_data_with_ov!AW$3:AW$1334,[1]ACSDT5Y2020.B08301_data_with_ov!$AS$3:$AS$1334,$B11) -> #VALUE! | P11: =SUMIFS([1]ACSDT5Y2020.B08301_data_with_ov!AX$3:AX$1334,[1]ACSDT5Y2020.B08301_data_with_ov!$AS$3:$AS$1334,$B11) -> #VALUE! | Q11: =SUMIFS([1]ACSDT5Y2020.B08301_data_with_ov!AY$3:AY$1334,[1]ACSDT5Y2020.B08301_data_with_ov!$AS$3:$AS$1334,$B11) -> #VALUE! | R11: =SUMIFS([1]ACSDT5Y2020.B08301_data_with_ov!AZ$3:AZ$1334,[1]ACSDT5Y2020.B08301_data_with_ov!$AS$3:$AS$1334,$B11) -> #VALUE! | S11: =SUMIFS([1]ACSDT5Y2020.B08301_data_with_ov!BA$3:BA$1334,[1]ACSDT5Y2020.B08301_data_with_ov!$AS$3:$AS$1334,$B11) -> #VALUE! | T11: 0.31927751 | U11: =(T11/$G11)*$L11 -> #VALUE! | V11: 0.31927751 | W11: =(V11/$G11)*$L11 -> #VALUE! | X11: 0.31927751 | Y11: =(X11/$G11)*$L11 -> #VALUE! | Z11: 0.31927751 | AA11: =(Z11/$G11)*$L11 -> #VALUE!
