Workbook
Name Date_End: Dashboard!$A$6
Name Date_Start: Dashboard!$A$5
Name R_Bike_Install_BBL: _xlfn.ANCHORARRAY(R_Dashboard!$B$41)
Name R_Bike_Install_BL: _xlfn.ANCHORARRAY(R_Dashboard!$B$42)
Name R_Bike_Install_LS: _xlfn.ANCHORARRAY(R_Dashboard!$B$60)
Name R_Bike_Install_LS_Per: _xlfn.ANCHORARRAY(R_Dashboard!$B$63)
Name R_Bike_Install_NG: _xlfn.ANCHORARRAY(R_Dashboard!$B$43)
Name R_Bike_Install_Off_T: _xlfn.ANCHORARRAY(R_Dashboard!$B$49)
Name R_Bike_Install_On_T: _xlfn.ANCHORARRAY(R_Dashboard!$B$45)
Name R_Bike_Install_Other: _xlfn.ANCHORARRAY(R_Dashboard!$B$57)
Name R_Bike_Install_Path: _xlfn.ANCHORARRAY(R_Dashboard!$B$47)
Name R_Bike_Install_PBL: _xlfn.ANCHORARRAY(R_Dashboard!$B$40)
Name R_Bike_Install_PBLA: _xlfn.ANCHORARRAY(R_Dashboard!$B$54)
Name R_Bike_Install_PBLC: _xlfn.ANCHORARRAY(R_Dashboard!$B$39)
Name R_Bike_Install_SL: _xlfn.ANCHORARRAY(R_Dashboard!$B$44)
Name R_Bike_Install_T: _xlfn.ANCHORARRAY(R_Dashboard!$B$51)
Name R_Bike_Install_Trail: _xlfn.ANCHORARRAY(R_Dashboard!$B$48)
Name R_Bike_Net_BBL: _xlfn.ANCHORARRAY(R_Dashboard!$B$12)
Name R_Bike_Net_BL: _xlfn.ANCHORARRAY(R_Dashboard!$B$13)
Name R_Bike_Net_Growth: _xlfn.ANCHORARRAY(R_Dashboard!$B$24)
Name R_Bike_Net_LS: _xlfn.ANCHORARRAY(R_Dashboard!$B$32)
Name R_Bike_Net_LS_Per: _xlfn.ANCHORARRAY(R_Dashboard!$B$35)
Name R_Bike_Net_NG: _xlfn.ANCHORARRAY(R_Dashboard!$B$14)
Name R_Bike_Net_Off_T: _xlfn.ANCHORARRAY(R_Dashboard!$B$20)
Name R_Bike_Net_On_T: _xlfn.ANCHORARRAY(R_Dashboard!$B$16)
Name R_Bike_Net_Other: _xlfn.ANCHORARRAY(R_Dashboard!$B$29)
Name R_Bike_Net_Path: _xlfn.ANCHORARRAY(R_Dashboard!$B$18)
Name R_Bike_Net_PBL: _xlfn.ANCHORARRAY(R_Dashboard!$B$11)
Name R_Bike_Net_SL: _xlfn.ANCHORARRAY(R_Dashboard!$B$15)
Name R_Bike_Net_T: _xlfn.ANCHORARRAY(R_Dashboard!$B$22)
Name R_Bike_Net_Trail: _xlfn.ANCHORARRAY(R_Dashboard!$B$19)
Name R_Date: _xlfn.ANCHORARRAY(R_Dashboard!$B$8)

Sheet Dashboard
A1: CDOT Complete Streets
A2: Program Dashboard
A5: 2010 | B5: Start | AA5: <--- Start year of charts
A6: 2025 | B6: End | C6: Emanuel 1 | G6: Emanuel 2 | K6: Lightfoot 1 | O6: Johnson 1 | AA6: <--- End year of charts
A8: Facility | B8: 2010 | C8: 2011 | D8: 2012 | E8: 2013 | F8: 2014 | G8: 2015 | H8: 2016 | I8: 2017 | J8: 2018 | K8: 2019 | L8: 2020 | M8: 2021 | N8: 2022 | O8: 2023 | P8: 2024 | Q8: 2025 | S8: Since 2018
A9: Bikeways
A10: Bikeway Network | Z10: Centerline Miles
A11: Protected Bike Lane | C11: 2 | D11: 11.4 | E11: 15.5 | F11: 18.5 | G11: 21.35 | H11: 22.55 | I11: 22.5 | J11: 23.45068 | K11: 24.3 | L11: 26.7 | M11: 35.220585 | N11: 37.56 | O11: 47.2 | P11: 57.3 | Q11: 68.7 | S11: =Q11-I11 -> 46.2
A12: Buffered Bike Lane | C12: 1 | D12: 18.65 | E12: 33.5 | F12: 67 | G12: 87 | H12: 88.8 | I12: 95.1 | J12: 105.88543 | K12: 107.5 | L12: 110.5 | M12: 113.96737 | N12: 115.57 | O12: 110.1 | P12: 107.8 | Q12: 106.5 | S12: =Q12-I12 -> 11.4
A13: Bike Lane | B13: 116 | C13: 133 | D13: 134.2 | E13: 117.5 | F13: 99 | G13: 88.5 | H13: 85.6 | I13: 82.7 | J13: 83.228266 | K13: 88 | L13: 103.3 | M13: 113.05001 | N13: 126.1 | O13: 130.4 | P13: 136.95 | Q13: 138.5 | S13: =Q13-I13 -> 55.8
A14: Neighborhood | E14: 1 | F14: 1.5 | G14: 1.5 | H14: 2.1 | I14: 3.2 | J14: 11.448655 | K14: 14.4 | L14: 17.4 | M14: 26.850629 | N14: 39.17 | O14: 57.2 | P14: 71.95 | Q14: 85.2 | S14: =Q14-I14 -> 82
A15: Shared Lane | B15: 30 | C15: 39 | D15: 39.85 | E15: 40 | F15: 41.5 | G15: 45.7 | H15: 45.7 | I15: 45.4 | J15: 45.474801 | K15: 44.4 | L15: 44.9 | M15: 52.026725 | N15: 49.74 | O15: 48.3 | P15: 47.6 | Q15: 46.98 | S15: =Q15-I15 -> 1.58
A16: TOTAL ON-STREET | B16: =IF(ISBLANK(B$8),"",SUM(B11:B15)) -> 146 | C16: =IF(ISBLANK(C$8),"",SUM(C11:C15)) -> 175 | D16: =IF(ISBLANK(D$8),"",SUM(D11:D15)) -> 204.1 | E16: =IF(ISBLANK(E$8),"",SUM(E11:E15)) -> 207.5 | F16: =IF(ISBLANK(F$8),"",SUM(F11:F15)) -> 227.5 | G16: =IF(ISBLANK(G$8),"",SUM(G11:G15)) -> 244.05 | H16: =IF(ISBLANK(H$8),"",SUM(H11:H15)) -> 244.75 | I16: =IF(ISBLANK(I$8),"",SUM(I11:I15)) -> 248.9 | ... X16: =IF(ISBLANK(X$8),"",SUM(X11:X15))
A18: Access Path | P18: 5.8 | Q18: 5.8 | S18: =Q18-I18 -> 5.8
A19: Off-Street Trail | B19: 47.2 | C19: 47.2 | D19: 47.76 | E19: 47.76 | F19: 47.76 | G19: 51.53 | H19: 51.81 | I19: 54.62 | J19: 54.92 | K19: 54.92 | L19: 55.27 | M19: 55.27 | N19: 55.27 | O19: 55.3 | P19: 49.5 | Q19: 49.5 | S19: =Q19-I19 -> -5.12
A20: TOTAL OFF-STREET | B20: =IF(ISBLANK(B$8),"",SUM(B18:B19)) -> 47.2 | C20: =IF(ISBLANK(C$8),"",SUM(C18:C19)) -> 47.2 | D20: =IF(ISBLANK(D$8),"",SUM(D18:D19)) -> 47.76 | E20: =IF(ISBLANK(E$8),"",SUM(E18:E19)) -> 47.76 | F20: =IF(ISBLANK(F$8),"",SUM(F18:F19)) -> 47.76 | G20: =IF(ISBLANK(G$8),"",SUM(G18:G19)) -> 51.53 | H20: =IF(ISBLANK(H$8),"",SUM(H18:H19)) -> 51.81 | I20: =IF(ISBLANK(I$8),"",SUM(I18:I19)) -> 54.62 | ... X20: =IF(ISBLANK(X$8),"",SUM(X18:X19))
A22: TOTAL NETWORK | B22: =IF(ISBLANK(B$8),"",SUM(B16,B20)) -> 193.2 | C22: =IF(ISBLANK(C$8),"",SUM(C16,C20)) -> 222.2 | D22: =IF(ISBLANK(D$8),"",SUM(D16,D20)) -> 251.86 | E22: =IF(ISBLANK(E$8),"",SUM(E16,E20)) -> 255.26 | F22: =IF(ISBLANK(F$8),"",SUM(F16,F20)) -> 275.26 | G22: =IF(ISBLANK(G$8),"",SUM(G16,G20)) -> 295.58 | H22: =IF(ISBLANK(H$8),"",SUM(H16,H20)) -> 296.56 | I22: =IF(ISBLANK(I$8),"",SUM(I16,I20)) -> 303.52 | ... X22: =IF(ISBLANK(X$8),"",SUM(X16,X20))
A24: Network Growth (from Prev Year) | C24: =IF(ISBLANK(C$8),"",C22-B22) -> 29 | D24: =IF(ISBLANK(D$8),"",D22-C22) -> 29.66 | E24: =IF(ISBLANK(E$8),"",E22-D22) -> 3.4 | F24: =IF(ISBLANK(F$8),"",F22-E22) -> 20 | G24: =IF(ISBLANK(G$8),"",G22-F22) -> 20.32 | H24: =IF(ISBLANK(H$8),"",H22-G22) -> 0.98 | I24: =IF(ISBLANK(I$8),"",I22-H22) -> 6.96 | J24: =IF(ISBLANK(J$8),"",J22-I22) -> 20.887835 | ... X24: =IF(ISBLANK(X$8),"",X22-W22)
A26: Protected Bike Lanes | B26: =IF(ISBLANK(B$8),"",B11) -> 0 | C26: =IF(ISBLANK(C$8),"",C11) -> 2 | D26: =IF(ISBLANK(D$8),"",D11) -> 11.4 | E26: =IF(ISBLANK(E$8),"",E11) -> 15.5 | F26: =IF(ISBLANK(F$8),"",F11) -> 18.5 | G26: =IF(ISBLANK(G$8),"",G11) -> 21.35 | H26: =IF(ISBLANK(H$8),"",H11) -> 22.55 | I26: =IF(ISBLANK(I$8),"",I11) -> 22.5 | ... X26: =IF(ISBLANK(X$8),"",X11)
A27: Neighborhood Greenways | B27: =IF(ISBLANK(B$8),"",B14) -> 0 | C27: =IF(ISBLANK(C$8),"",C14) -> 0 | D27: =IF(ISBLANK(D$8),"",D14) -> 0 | E27: =IF(ISBLANK(E$8),"",E14) -> 1 | F27: =IF(ISBLANK(F$8),"",F14) -> 1.5 | G27: =IF(ISBLANK(G$8),"",G14) -> 1.5 | H27: =IF(ISBLANK(H$8),"",H14) -> 2.1 | I27: =IF(ISBLANK(I$8),"",I14) -> 3.2 | ... X27: =IF(ISBLANK(X$8),"",X14)
A28: Off-Street Trails | B28: =IF(ISBLANK(B$8),"",B20) -> 47.2 | C28: =IF(ISBLANK(C$8),"",C20) -> 47.2 | D28: =IF(ISBLANK(D$8),"",D20) -> 47.76 | E28: =IF(ISBLANK(E$8),"",E20) -> 47.76 | F28: =IF(ISBLANK(F$8),"",F20) -> 47.76 | G28: =IF(ISBLANK(G$8),"",G20) -> 51.53 | H28: =IF(ISBLANK(H$8),"",H20) -> 51.81 | I28: =IF(ISBLANK(I$8),"",I20) -> 54.62 | ... X28: =IF(ISBLANK(X$8),"",X20)
A29: Other Bikeways | B29: =IF(ISBLANK(B$8),"",B22-SUM(B26:B28)) -> 146 | C29: =IF(ISBLANK(C$8),"",C22-SUM(C26:C28)) -> 173 | D29: =IF(ISBLANK(D$8),"",D22-SUM(D26:D28)) -> 192.7 | E29: =IF(ISBLANK(E$8),"",E22-SUM(E26:E28)) -> 191 | F29: =IF(ISBLANK(F$8),"",F22-SUM(F26:F28)) -> 207.5 | G29: =IF(ISBLANK(G$8),"",G22-SUM(G26:G28)) -> 221.2 | H29: =IF(ISBLANK(H$8),"",H22-SUM(H26:H28)) -> 220.1 | I29: =IF(ISBLANK(I$8),"",I22-SUM(I26:I28)) -> 223.2 | ... X29: =IF(ISBLANK(X$8),"",X22-SUM(X26:X28))
A32: Low-Stress Bikeways | B32: =IF(ISBLANK(B$8),"",SUM(B26:B28)) -> 47.2 | C32: =IF(ISBLANK(C$8),"",SUM(C26:C28)) -> 49.2 | D32: =IF(ISBLANK(D$8),"",SUM(D26:D28)) -> 59.16 | E32: =IF(ISBLANK(E$8),"",SUM(E26:E28)) -> 64.26 | F32: =IF(ISBLANK(F$8),"",SUM(F26:F28)) -> 67.76 | G32: =IF(ISBLANK(G$8),"",SUM(G26:G28)) -> 74.38 | H32: =IF(ISBLANK(H$8),"",SUM(H26:H28)) -> 76.46 | I32: =IF(ISBLANK(I$8),"",SUM(I26:I28)) -> 80.32 | ... X32: =IF(ISBLANK(X$8),"",SUM(X26:X28))
A33: Other Bikeways | B33: =B29 -> 146 | C33: =C29 -> 173 | D33: =D29 -> 192.7 | E33: =E29 -> 191 | F33: =F29 -> 207.5 | G33: =G29 -> 221.2 | H33: =H29 -> 220.1 | I33: =I29 -> 223.2 | ... X33: =X29
A35: % Low-Stress | B35: =IF(ISBLANK(B$8),"",B32/B22) -> 0.24430642 | C35: =IF(ISBLANK(C$8),"",C32/C22) -> 0.22142214 | D35: =IF(ISBLANK(D$8),"",D32/D22) -> 0.2348924 | E35: =IF(ISBLANK(E$8),"",E32/E22) -> 0.25174332 | F35: =IF(ISBLANK(F$8),"",F32/F22) -> 0.24616726 | G35: =IF(ISBLANK(G$8),"",G32/G22) -> 0.25164084 | H35: =IF(ISBLANK(H$8),"",H32/H22) -> 0.25782304 | I35: =IF(ISBLANK(I$8),"",I32/I22) -> 0.26462836 | ... X35: =IF(ISBLANK(X$8),"",X32/X22)
A37: Protected Bike Lanes | B37: =IF(ISBLANK(B$8),"",B26/B$22) -> 0 | C37: =IF(ISBLANK(C$8),"",C26/C$22) -> 0.0090009001 | D37: =IF(ISBLANK(D$8),"",D26/D$22) -> 0.045263241 | E37: =IF(ISBLANK(E$8),"",E26/E$22) -> 0.060722401 | F37: =IF(ISBLANK(F$8),"",F26/F$22) -> 0.067209184 | G37: =IF(ISBLANK(G$8),"",G26/G$22) -> 0.072230868 | H37: =IF(ISBLANK(H$8),"",H26/H$22) -> 0.076038576 | I37: =IF(ISBLANK(I$8),"",I26/I$22) -> 0.074130206 | ... X37: =IF(ISBLANK(X$8),"",X26/X$22)
A38: Neighborhood Greenways | B38: =IF(ISBLANK(B$8),"",B27/B$22) -> 0 | C38: =IF(ISBLANK(C$8),"",C27/C$22) -> 0 | D38: =IF(ISBLANK(D$8),"",D27/D$22) -> 0 | E38: =IF(ISBLANK(E$8),"",E27/E$22) -> 0.0039175742 | F38: =IF(ISBLANK(F$8),"",F27/F$22) -> 0.0054493933 | G38: =IF(ISBLANK(G$8),"",G27/G$22) -> 0.0050747683 | H38: =IF(ISBLANK(H$8),"",H27/H$22) -> 0.0070811977 | I38: =IF(ISBLANK(I$8),"",I27/I$22) -> 0.010542963 | ... X38: =IF(ISBLANK(X$8),"",X27/X$22)
A39: Off-Street Trails | B39: =IF(ISBLANK(B$8),"",B28/B$22) -> 0.24430642 | C39: =IF(ISBLANK(C$8),"",C28/C$22) -> 0.21242124 | D39: =IF(ISBLANK(D$8),"",D28/D$22) -> 0.18962916 | E39: =IF(ISBLANK(E$8),"",E28/E$22) -> 0.18710335 | F39: =IF(ISBLANK(F$8),"",F28/F$22) -> 0.17350868 | G39: =IF(ISBLANK(G$8),"",G28/G$22) -> 0.17433521 | H39: =IF(ISBLANK(H$8),"",H28/H$22) -> 0.17470326 | I39: =IF(ISBLANK(I$8),"",I28/I$22) -> 0.17995519 | ... X39: =IF(ISBLANK(X$8),"",X28/X$22)
A40: Other Bikeways | B40: =IF(ISBLANK(B$8),"",B29/B$22) -> 0.75569358 | C40: =IF(ISBLANK(C$8),"",C29/C$22) -> 0.77857786 | D40: =IF(ISBLANK(D$8),"",D29/D$22) -> 0.7651076 | E40: =IF(ISBLANK(E$8),"",E29/E$22) -> 0.74825668 | F40: =IF(ISBLANK(F$8),"",F29/F$22) -> 0.75383274 | G40: =IF(ISBLANK(G$8),"",G29/G$22) -> 0.74835916 | H40: =IF(ISBLANK(H$8),"",H29/H$22) -> 0.74217696 | I40: =IF(ISBLANK(I$8),"",I29/I$22) -> 0.73537164 | ... X40: =IF(ISBLANK(X$8),"",X29/X$22)
A43: Low-Stress Bikeways | B43: =IF(ISBLANK(B$8),"",SUM(B37:B39)) -> 0.24430642 | C43: =IF(ISBLANK(C$8),"",SUM(C37:C39)) -> 0.22142214 | D43: =IF(ISBLANK(D$8),"",SUM(D37:D39)) -> 0.2348924 | E43: =IF(ISBLANK(E$8),"",SUM(E37:E39)) -> 0.25174332 | F43: =IF(ISBLANK(F$8),"",SUM(F37:F39)) -> 0.24616726 | G43: =IF(ISBLANK(G$8),"",SUM(G37:G39)) -> 0.25164084 | H43: =IF(ISBLANK(H$8),"",SUM(H37:H39)) -> 0.25782304 | I43: =IF(ISBLANK(I$8),"",SUM(I37:I39)) -> 0.26462836 | ... X43: =IF(ISBLANK(X$8),"",SUM(X37:X39))
A44: Other Bikeways | B44: =B40 -> 0.75569358 | C44: =C40 -> 0.77857786 | D44: =D40 -> 0.7651076 | E44: =E40 -> 0.74825668 | F44: =F40 -> 0.75383274 | G44: =G40 -> 0.74835916 | H44: =H40 -> 0.74217696 | I44: =I40 -> 0.73537164 | ... X44: =X40
A47: Bikeways Installs | Z47: Centerline Miles
A48: Concrete PBL Upgrade | J48: 2.36 | K48: 1.69 | N48: 2.64 | O48: 17.56 | P48: 3.5 | Q48: 0.98 | S48: =SUM(J48:R48) -> 28.73 | X48: =SUM(O48:Q48) -> 22.04
A49: Protected Bike Lane | C49: 2 | D49: 9.25 | E49: 4 | F49: 3.25 | G49: 3.35 | H49: 1.2 | I49: 1.2 | J49: 1 | K49: 0.76 | L49: 2.4 | M49: 8.5 | N49: 2.36 | O49: 9.49 | P49: 11.7 | Q49: 11.41 | S49: =SUM(J49:R49) -> 47.62 | X49: =SUM(O49:Q49) -> 32.6
A50: Buffered Bike Lane | C50: 1 | D50: 17.65 | E50: 15 | F50: 33.25 | G50: 20 | H50: 1.8 | I50: 8.9 | J50: 10.82 | K50: 2.3 | L50: 3 | M50: 3.91 | N50: 3.08 | O50: 0.15 | P50: 2.4 | Q50: 0.76 | S50: =SUM(J50:R50) -> 26.42 | X50: =SUM(O50:Q50) -> 3.31
A51: Bike Lane | C51: 17 | D51: 1.2 | E51: 2.25 | F51: 2.5 | G51: 0.5 | H51: 1.3 | I51: 3.3 | J51: 5.63 | K51: 4.8 | L51: 15.3 | M51: 16.34 | N51: 13.7 | O51: 5.53 | P51: 12.15 | Q51: 2.5 | S51: =SUM(J51:R51) -> 75.95 | X51: =SUM(O51:Q51) -> 20.18
A52: Neighborhood | E52: 1 | F52: 0.5 | H52: 0.75 | I52: 1.1 | J52: 7.92 | K52: 3 | L52: 3 | M52: 9.18 | N52: 12.3 | O52: 17.54 | P52: 15.25 | Q52: 13.67 | S52: =SUM(J52:R52) -> 81.86 | X52: =SUM(O52:Q52) -> 46.46
A53: Shared Lane | C53: 9 | D53: 0.85 | G53: 1.6 | I53: 3.7 | J53: 2.06 | K53: 0.5 | L53: 5.3 | M53: 6.3 | N53: 1 | O53: 0.12 | P53: 0.6 | Q53: 0.58 | S53: =SUM(J53:R53) -> 16.46 | X53: =SUM(O53:Q53) -> 1.3
A54: TOTAL ON-STREET | C54: =IF(ISBLANK(C$8),"",SUM(C48:C53)) -> 29 | D54: =IF(ISBLANK(D$8),"",SUM(D48:D53)) -> 28.95 | E54: =IF(ISBLANK(E$8),"",SUM(E48:E53)) -> 22.25 | F54: =IF(ISBLANK(F$8),"",SUM(F48:F53)) -> 39.5 | G54: =IF(ISBLANK(G$8),"",SUM(G48:G53)) -> 25.45 | H54: =IF(ISBLANK(H$8),"",SUM(H48:H53)) -> 5.05 | I54: =IF(ISBLANK(I$8),"",SUM(I48:I53)) -> 18.2 | J54: =IF(ISBLANK(J$8),"",SUM(J48:J53)) -> 29.79 | ... W54: =IF(ISBLANK(W$8),"",SUM(W48:W53)) | X54: =SUM(O54:Q54) -> 125.89
A56: Access Path | P56: 0 | Q56: 0 | S56: =SUM(J56:R56) -> 0 | X56: =SUM(O56:Q56) -> 0
...

Sheet R_Dashboard
A1: CDOT Complete Streets
A2: Program Dashboard
A4: Bikeways
A8: R_Date | B8: {=_xlfn._xlws.FILTER(Dashboard!$B8:$Y8,(Dashboard!$B$8:$Y$8>=Date_Start)*(Dashboard!$B$8:$Y$8<=Date_End),NA())} -> 2010 | C8: 2011 | D8: 2012 | E8: 2013 | F8: 2014 | G8: 2015 | H8: 2016 | I8: 2017 | J8: 2018 | K8: 2019 | L8: 2020 | M8: 2021 | N8: 2022 | O8: 2023 | P8: 2024 | Q8: 2025
A9: R_Bike
A10: R_Bike_Net
A11: R_Bike_Net_PBL | B11: {=_xlfn._xlws.FILTER(Dashboard!$B11:$Y11,(Dashboard!$B$8:$Y$8>=Date_Start)*(Dashboard!$B$8:$Y$8<=Date_End),NA())} -> 0 | C11: 2 | D11: 11.4 | E11: 15.5 | F11: 18.5 | G11: 21.35 | H11: 22.55 | I11: 22.5 | J11: 23.45068 | K11: 24.3 | L11: 26.7 | M11: 35.220585 | N11: 37.56 | O11: 47.2 | P11: 57.3 | Q11: 68.7
A12: R_Bike_Net_BBL | B12: {=_xlfn._xlws.FILTER(Dashboard!$B12:$Y12,(Dashboard!$B$8:$Y$8>=Date_Start)*(Dashboard!$B$8:$Y$8<=Date_End),NA())} -> 0 | C12: 1 | D12: 18.65 | E12: 33.5 | F12: 67 | G12: 87 | H12: 88.8 | I12: 95.1 | J12: 105.88543 | K12: 107.5 | L12: 110.5 | M12: 113.96737 | N12: 115.57 | O12: 110.1 | P12: 107.8 | Q12: 106.5
A13: R_Bike_Net_BL | B13: {=_xlfn._xlws.FILTER(Dashboard!$B13:$Y13,(Dashboard!$B$8:$Y$8>=Date_Start)*(Dashboard!$B$8:$Y$8<=Date_End),NA())} -> 116 | C13: 133 | D13: 134.2 | E13: 117.5 | F13: 99 | G13: 88.5 | H13: 85.6 | I13: 82.7 | J13: 83.228266 | K13: 88 | L13: 103.3 | M13: 113.05001 | N13: 126.1 | O13: 130.4 | P13: 136.95 | Q13: 138.5
A14: R_Bike_Net_NG | B14: {=_xlfn._xlws.FILTER(Dashboard!$B14:$Y14,(Dashboard!$B$8:$Y$8>=Date_Start)*(Dashboard!$B$8:$Y$8<=Date_End),NA())} -> 0 | C14: 0 | D14: 0 | E14: 1 | F14: 1.5 | G14: 1.5 | H14: 2.1 | I14: 3.2 | J14: 11.448655 | K14: 14.4 | L14: 17.4 | M14: 26.850629 | N14: 39.17 | O14: 57.2 | P14: 71.95 | Q14: 85.2
A15: R_Bike_Net_SL | B15: {=_xlfn._xlws.FILTER(Dashboard!$B15:$Y15,(Dashboard!$B$8:$Y$8>=Date_Start)*(Dashboard!$B$8:$Y$8<=Date_End),NA())} -> 30 | C15: 39 | D15: 39.85 | E15: 40 | F15: 41.5 | G15: 45.7 | H15: 45.7 | I15: 45.4 | J15: 45.474801 | K15: 44.4 | L15: 44.9 | M15: 52.026725 | N15: 49.74 | O15: 48.3 | P15: 47.6 | Q15: 46.98
A16: R_Bike_Net_On_T | B16: {=_xlfn._xlws.FILTER(Dashboard!$B16:$Y16,(Dashboard!$B$8:$Y$8>=Date_Start)*(Dashboard!$B$8:$Y$8<=Date_End),NA())} -> 146 | C16: 175 | D16: 204.1 | E16: 207.5 | F16: 227.5 | G16: 244.05 | H16: 244.75 | I16: 248.9 | J16: 269.48784 | K16: 278.6 | L16: 302.8 | M16: 341.11532 | N16: 368.14 | O16: 393.2 | P16: 421.6 | Q16: 445.88
A18: R_Bike_Net_Path | B18: {=_xlfn._xlws.FILTER(Dashboard!$B18:$Y18,(Dashboard!$B$8:$Y$8>=Date_Start)*(Dashboard!$B$8:$Y$8<=Date_End),NA())} -> 0 | C18: 0 | D18: 0 | E18: 0 | F18: 0 | G18: 0 | H18: 0 | I18: 0 | J18: 0 | K18: 0 | L18: 0 | M18: 0 | N18: 0 | O18: 0 | P18: 5.8 | Q18: 5.8
A19: R_Bike_Net_Trail | B19: {=_xlfn._xlws.FILTER(Dashboard!$B19:$Y19,(Dashboard!$B$8:$Y$8>=Date_Start)*(Dashboard!$B$8:$Y$8<=Date_End),NA())} -> 47.2 | C19: 47.2 | D19: 47.76 | E19: 47.76 | F19: 47.76 | G19: 51.53 | H19: 51.81 | I19: 54.62 | J19: 54.92 | K19: 54.92 | L19: 55.27 | M19: 55.27 | N19: 55.27 | O19: 55.3 | P19: 49.5 | Q19: 49.5
A20: R_Bike_Net_Off_T | B20: {=_xlfn._xlws.FILTER(Dashboard!$B20:$Y20,(Dashboard!$B$8:$Y$8>=Date_Start)*(Dashboard!$B$8:$Y$8<=Date_End),NA())} -> 47.2 | C20: 47.2 | D20: 47.76 | E20: 47.76 | F20: 47.76 | G20: 51.53 | H20: 51.81 | I20: 54.62 | J20: 54.92 | K20: 54.92 | L20: 55.27 | M20: 55.27 | N20: 55.27 | O20: 55.3 | P20: 55.3 | Q20: 55.3
A22: R_Bike_Net_T | B22: {=_xlfn._xlws.FILTER(Dashboard!$B22:$Y22,(Dashboard!$B$8:$Y$8>=Date_Start)*(Dashboard!$B$8:$Y$8<=Date_End),NA())} -> 193.2 | C22: 222.2 | D22: 251.86 | E22: 255.26 | F22: 275.26 | G22: 295.58 | H22: 296.56 | I22: 303.52 | J22: 324.40784 | K22: 333.52 | L22: 358.07 | M22: 396.38532 | N22: 423.41 | O22: 448.5 | P22: 476.9 | Q22: 501.18
A24: R_Bike_Net_Growth | B24: {=_xlfn._xlws.FILTER(Dashboard!$B24:$Y24,(Dashboard!$B$8:$Y$8>=Date_Start)*(Dashboard!$B$8:$Y$8<=Date_End),NA())} -> 0 | C24: 29 | D24: 29.66 | E24: 3.4 | F24: 20 | G24: 20.32 | H24: 0.98 | I24: 6.96 | J24: 20.887835 | K24: 9.1121648 | L24: 24.55 | M24: 38.31532 | N24: 27.02468 | O24: 25.09 | P24: 28.4 | Q24: 24.28
A26: =A11 -> R_Bike_Net_PBL | B26: {=_xlfn._xlws.FILTER(Dashboard!$B26:$Y26,(Dashboard!$B$8:$Y$8>=Date_Start)*(Dashboard!$B$8:$Y$8<=Date_End),NA())} -> 0 | C26: 2 | D26: 11.4 | E26: 15.5 | F26: 18.5 | G26: 21.35 | H26: 22.55 | I26: 22.5 | J26: 23.45068 | K26: 24.3 | L26: 26.7 | M26: 35.220585 | N26: 37.56 | O26: 47.2 | P26: 57.3 | Q26: 68.7
A27: =A14 -> R_Bike_Net_NG | B27: {=_xlfn._xlws.FILTER(Dashboard!$B27:$Y27,(Dashboard!$B$8:$Y$8>=Date_Start)*(Dashboard!$B$8:$Y$8<=Date_End),NA())} -> 0 | C27: 0 | D27: 0 | E27: 1 | F27: 1.5 | G27: 1.5 | H27: 2.1 | I27: 3.2 | J27: 11.448655 | K27: 14.4 | L27: 17.4 | M27: 26.850629 | N27: 39.17 | O27: 57.2 | P27: 71.95 | Q27: 85.2
A28: =A20 -> R_Bike_Net_Off_T | B28: {=_xlfn._xlws.FILTER(Dashboard!$B28:$Y28,(Dashboard!$B$8:$Y$8>=Date_Start)*(Dashboard!$B$8:$Y$8<=Date_End),NA())} -> 47.2 | C28: 47.2 | D28: 47.76 | E28: 47.76 | F28: 47.76 | G28: 51.53 | H28: 51.81 | I28: 54.62 | J28: 54.92 | K28: 54.92 | L28: 55.27 | M28: 55.27 | N28: 55.27 | O28: 55.3 | P28: 55.3 | Q28: 55.3
A29: R_Bike_Net_Other | B29: {=_xlfn._xlws.FILTER(Dashboard!$B29:$Y29,(Dashboard!$B$8:$Y$8>=Date_Start)*(Dashboard!$B$8:$Y$8<=Date_End),NA())} -> 146 | C29: 173 | D29: 192.7 | E29: 191 | F29: 207.5 | G29: 221.2 | H29: 220.1 | I29: 223.2 | J29: 234.5885 | K29: 239.9 | L29: 258.7 | M29: 279.04411 | N29: 291.41 | O29: 288.8 | P29: 292.35 | Q29: 291.98
A32: R_Bike_Net_LS | B32: {=_xlfn._xlws.FILTER(Dashboard!$B32:$Y32,(Dashboard!$B$8:$Y$8>=Date_Start)*(Dashboard!$B$8:$Y$8<=Date_End),NA())} -> 47.2 | C32: 49.2 | D32: 59.16 | E32: 64.26 | F32: 67.76 | G32: 74.38 | H32: 76.46 | I32: 80.32 | J32: 89.819334 | K32: 93.62 | L32: 99.37 | M32: 117.34121 | N32: 132 | O32: 159.7 | P32: 184.55 | Q32: 209.2
A33: =A29 -> R_Bike_Net_Other | B33: {=_xlfn._xlws.FILTER(Dashboard!$B33:$Y33,(Dashboard!$B$8:$Y$8>=Date_Start)*(Dashboard!$B$8:$Y$8<=Date_End),NA())} -> 146 | C33: 173 | D33: 192.7 | E33: 191 | F33: 207.5 | G33: 221.2 | H33: 220.1 | I33: 223.2 | J33: 234.5885 | K33: 239.9 | L33: 258.7 | M33: 279.04411 | N33: 291.41 | O33: 288.8 | P33: 292.35 | Q33: 291.98
A35: R_Bike_Net_LS_Per | B35: {=_xlfn._xlws.FILTER(Dashboard!$B35:$Y35,(Dashboard!$B$8:$Y$8>=Date_Start)*(Dashboard!$B$8:$Y$8<=Date_End),NA())} -> 0.24430642 | C35: 0.22142214 | D35: 0.2348924 | E35: 0.25174332 | F35: 0.24616726 | G35: 0.25164084 | H35: 0.25782304 | I35: 0.26462836 | J35: 0.27687166 | K35: 0.28070281 | L35: 0.27751557 | M35: 0.29602815 | N35: 0.31175456 | O35: 0.35607581 | P35: 0.3869784 | Q35: 0.4174149
A38: B_Install
A39: R_Bike_Install_PBLC | B39: {=_xlfn._xlws.FILTER(Dashboard!$B48:$Y48,(Dashboard!$B$8:$Y$8>=Date_Start)*(Dashboard!$B$8:$Y$8<=Date_End),NA())} -> 0 | C39: 0 | D39: 0 | E39: 0 | F39: 0 | G39: 0 | H39: 0 | I39: 0 | J39: 2.36 | K39: 1.69 | L39: 0 | M39: 0 | N39: 2.64 | O39: 17.56 | P39: 3.5 | Q39: 0.98
A40: R_Bike_Install_PBL | B40: {=_xlfn._xlws.FILTER(Dashboard!$B49:$Y49,(Dashboard!$B$8:$Y$8>=Date_Start)*(Dashboard!$B$8:$Y$8<=Date_End),NA())} -> 0 | C40: 2 | D40: 9.25 | E40: 4 | F40: 3.25 | G40: 3.35 | H40: 1.2 | I40: 1.2 | J40: 1 | K40: 0.76 | L40: 2.4 | M40: 8.5 | N40: 2.36 | O40: 9.49 | P40: 11.7 | Q40: 11.41
A41: R_Bike_Install_BBL | B41: {=_xlfn._xlws.FILTER(Dashboard!$B50:$Y50,(Dashboard!$B$8:$Y$8>=Date_Start)*(Dashboard!$B$8:$Y$8<=Date_End),NA())} -> 0 | C41: 1 | D41: 17.65 | E41: 15 | F41: 33.25 | G41: 20 | H41: 1.8 | I41: 8.9 | J41: 10.82 | K41: 2.3 | L41: 3 | M41: 3.91 | N41: 3.08 | O41: 0.15 | P41: 2.4 | Q41: 0.76
A42: R_Bike_Install_BL | B42: {=_xlfn._xlws.FILTER(Dashboard!$B51:$Y51,(Dashboard!$B$8:$Y$8>=Date_Start)*(Dashboard!$B$8:$Y$8<=Date_End),NA())} -> 0 | C42: 17 | D42: 1.2 | E42: 2.25 | F42: 2.5 | G42: 0.5 | H42: 1.3 | I42: 3.3 | J42: 5.63 | K42: 4.8 | L42: 15.3 | M42: 16.34 | N42: 13.7 | O42: 5.53 | P42: 12.15 | Q42: 2.5
A43: R_Bike_Install_NG | B43: {=_xlfn._xlws.FILTER(Dashboard!$B52:$Y52,(Dashboard!$B$8:$Y$8>=Date_Start)*(Dashboard!$B$8:$Y$8<=Date_End),NA())} -> 0 | C43: 0 | D43: 0 | E43: 1 | F43: 0.5 | G43: 0 | H43: 0.75 | I43: 1.1 | J43: 7.92 | K43: 3 | L43: 3 | M43: 9.18 | N43: 12.3 | O43: 17.54 | P43: 15.25 | Q43: 13.67
A44: R_Bike_Install_SL | B44: {=_xlfn._xlws.FILTER(Dashboard!$B53:$Y53,(Dashboard!$B$8:$Y$8>=Date_Start)*(Dashboard!$B$8:$Y$8<=Date_End),NA())} -> 0 | C44: 9 | D44: 0.85 | E44: 0 | F44: 0 | G44: 1.6 | H44: 0 | I44: 3.7 | J44: 2.06 | K44: 0.5 | L44: 5.3 | M44: 6.3 | N44: 1 | O44: 0.12 | P44: 0.6 | Q44: 0.58
A45: R_Bike_Install_On_T | B45: {=_xlfn._xlws.FILTER(Dashboard!$B54:$Y54,(Dashboard!$B$8:$Y$8>=Date_Start)*(Dashboard!$B$8:$Y$8<=Date_End),NA())} -> 0 | C45: 29 | D45: 28.95 | E45: 22.25 | F45: 39.5 | G45: 25.45 | H45: 5.05 | I45: 18.2 | J45: 29.79 | K45: 13.05 | L45: 29 | M45: 44.23 | N45: 35.08 | O45: 50.39 | P45: 45.6 | Q45: 29.9
A47: R_Bike_Install_Path | B47: {=_xlfn._xlws.FILTER(Dashboard!$B56:$Y56,(Dashboard!$B$8:$Y$8>=Date_Start)*(Dashboard!$B$8:$Y$8<=Date_End),NA())} -> 0 | C47: 0 | D47: 0 | E47: 0 | F47: 0 | G47: 0 | H47: 0 | I47: 0 | J47: 0 | K47: 0 | L47: 0 | M47: 0 | N47: 0 | O47: 0 | P47: 0 | Q47: 0
A48: R_Bike_Install_Trail | B48: {=_xlfn._xlws.FILTER(Dashboard!$B57:$Y57,(Dashboard!$B$8:$Y$8>=Date_Start)*(Dashboard!$B$8:$Y$8<=Date_End),NA())} -> 0 | C48: 0 | D48: 0.56 | E48: 0 | F48: 0 | G48: 3.77 | H48: 0.28 | I48: 2.81 | J48: 0.3 | K48: 0 | L48: 0.35 | M48: 0 | N48: 0 | O48: 0.03 | P48: 0 | Q48: 0
A49: R_Bike_Install_Off_T | B49: {=_xlfn._xlws.FILTER(Dashboard!$B58:$Y58,(Dashboard!$B$8:$Y$8>=Date_Start)*(Dashboard!$B$8:$Y$8<=Date_End),NA())} -> 0 | C49: 0 | D49: 0.56 | E49: 0 | F49: 0 | G49: 3.77 | H49: 0.28 | I49: 2.81 | J49: 0.3 | K49: 0 | L49: 0.35 | M49: 0 | N49: 0 | O49: 0.03 | P49: 0 | Q49: 0
A51: R_Bike_Install_T | B51: {=_xlfn._xlws.FILTER(Dashboard!$B60:$Y60,(Dashboard!$B$8:$Y$8>=Date_Start)*(Dashboard!$B$8:$Y$8<=Date_End),NA())} -> 0 | C51: 29 | D51: 29.51 | E51: 22.25 | F51: 39.5 | G51: 29.22 | H51: 5.33 | I51: 21.01 | J51: 30.09 | K51: 13.05 | L51: 29.35 | M51: 44.23 | N51: 35.08 | O51: 50.42 | P51: 45.6 | Q51: 29.9
A54: R_Bike_Install_PBLA | B54: {=_xlfn._xlws.FILTER(Dashboard!$B63:$Y63,(Dashboard!$B$8:$Y$8>=Date_Start)*(Dashboard!$B$8:$Y$8<=Date_End),NA())} -> 0 | C54: 2 | D54: 9.25 | E54: 4 | F54: 3.25 | G54: 3.35 | H54: 1.2 | I54: 1.2 | J54: 3.36 | K54: 2.45 | L54: 2.4 | M54: 8.5 | N54: 5 | O54: 27.05 | P54: 15.2 | Q54: 12.39
A55: =A43 -> R_Bike_Install_NG | B55: {=_xlfn._xlws.FILTER(Dashboard!$B64:$Y64,(Dashboard!$B$8:$Y$8>=Date_Start)*(Dashboard!$B$8:$Y$8<=Date_End),NA())} -> 0 | C55: 0 | D55: 0 | E55: 1 | F55: 0.5 | G55: 0 | H55: 0.75 | I55: 1.1 | J55: 7.92 | K55: 3 | L55: 3 | M55: 9.18 | N55: 12.3 | O55: 17.54 | P55: 15.25 | Q55: 13.67
A56: =A49 -> R_Bike_Install_Off_T | B56: {=_xlfn._xlws.FILTER(Dashboard!$B65:$Y65,(Dashboard!$B$8:$Y$8>=Date_Start)*(Dashboard!$B$8:$Y$8<=Date_End),NA())} -> 0 | C56: 0 | D56: 0.56 | E56: 0 | F56: 0 | G56: 3.77 | H56: 0.28 | I56: 2.81 | J56: 0.3 | K56: 0 | L56: 0.35 | M56: 0 | N56: 0 | O56: 0.03 | P56: 0 | Q56: 0
A57: R_Bike_Install_Other | B57: {=_xlfn._xlws.FILTER(Dashboard!$B66:$Y66,(Dashboard!$B$8:$Y$8>=Date_Start)*(Dashboard!$B$8:$Y$8<=Date_End),NA())} -> 0 | C57: 27 | D57: 19.7 | E57: 17.25 | F57: 35.75 | G57: 22.1 | H57: 3.1 | I57: 15.9 | J57: 18.51 | K57: 7.6 | L57: 23.6 | M57: 26.55 | N57: 17.78 | O57: 5.8 | P57: 15.15 | Q57: 3.84
...

Sheet Equity
A1: Equity Dashboard
A2: CDOT Bike Program
B4: North Side | D4: West Side | E4: South Side | H4: Central
B5: 1 | C5: 2 | D5: 3 | E5: 6 | F5: 4 | G5: 5 | H5: 7 | R5: 3-B Community Sub-District moved from West to Central
B6: N | C6: NW | D6: W | E6: S | F6: SW | G6: FS | H6: C | I6: TOTAL | L6: North | M6: West | N6: South | O6: Central | P6: TOTAL
A7: Facilities by Geography | I7: Centerline Miles | K7: Facilities by Geography | P7: Centerline Miles
A8: Protected Bike Lanes | B8: {=SUMPRODUCT(--(Network_Bikeways!$N$11:$N$1010=$R8),Network_Bikeways!$AB$11:$AB$1010,Network_Bikeways!AM$11:AM$1010)} -> 2.2278947 | C8: {=SUMPRODUCT(--(Network_Bikeways!$N$11:$N$1010=$R8),Network_Bikeways!$AB$11:$AB$1010,Network_Bikeways!AN$11:AN$1010)} -> 2.9493142 | D8: {=SUMPRODUCT(--(Network_Bikeways!$N$11:$N$1010=$R8),Network_Bikeways!$AB$11:$AB$1010,Network_Bikeways!AO$11:AO$1010)} -> 8.9760821 | E8: {=SUMPRODUCT(--(Network_Bikeways!$N$11:$N$1010=$R8),Network_Bikeways!$AB$11:$AB$1010,Network_Bikeways!AP$11:AP$1010)} -> 2.8572781 | F8: {=SUMPRODUCT(--(Network_Bikeways!$N$11:$N$1010=$R8),Network_Bikeways!$AB$11:$AB$1010,Network_Bikeways!AQ$11:AQ$1010)} -> 0.85219917 | G8: {=SUMPRODUCT(--(Network_Bikeways!$N$11:$N$1010=$R8),Network_Bikeways!$AB$11:$AB$1010,Network_Bikeways!AR$11:AR$1010)} -> 4.8739501 | H8: {=SUMPRODUCT(--(Network_Bikeways!$N$11:$N$1010=$R8),Network_Bikeways!$AB$11:$AB$1010,Network_Bikeways!AS$11:AS$1010)} -> 15.771943 | I8: =SUM(B8:H8) -> 38.508661 | K8: Protected Bike Lanes | L8: =SUM(B8:C8) -> 5.1772089 | M8: =D8 -> 8.9760821 | N8: =SUM(E8:G8) -> 8.5834274 | O8: =H8 -> 15.771943 | P8: =SUM(L8:O8) -> 38.508661 | R8: PROTECTED BIKE LANE
A9: Buffered Bike Lanes | B9: {=SUMPRODUCT(--(Network_Bikeways!$N$11:$N$1010=$R9),Network_Bikeways!$AB$11:$AB$1010,Network_Bikeways!AM$11:AM$1010)} -> 8.0785891 | C9: {=SUMPRODUCT(--(Network_Bikeways!$N$11:$N$1010=$R9),Network_Bikeways!$AB$11:$AB$1010,Network_Bikeways!AN$11:AN$1010)} -> 18.263911 | D9: {=SUMPRODUCT(--(Network_Bikeways!$N$11:$N$1010=$R9),Network_Bikeways!$AB$11:$AB$1010,Network_Bikeways!AO$11:AO$1010)} -> 13.229945 | E9: {=SUMPRODUCT(--(Network_Bikeways!$N$11:$N$1010=$R9),Network_Bikeways!$AB$11:$AB$1010,Network_Bikeways!AP$11:AP$1010)} -> 23.441441 | F9: {=SUMPRODUCT(--(Network_Bikeways!$N$11:$N$1010=$R9),Network_Bikeways!$AB$11:$AB$1010,Network_Bikeways!AQ$11:AQ$1010)} -> 11.645923 | G9: {=SUMPRODUCT(--(Network_Bikeways!$N$11:$N$1010=$R9),Network_Bikeways!$AB$11:$AB$1010,Network_Bikeways!AR$11:AR$1010)} -> 15.303757 | H9: {=SUMPRODUCT(--(Network_Bikeways!$N$11:$N$1010=$R9),Network_Bikeways!$AB$11:$AB$1010,Network_Bikeways!AS$11:AS$1010)} -> 25.611029 | I9: =SUM(B9:H9) -> 115.5746 | K9: Buffered Bike Lanes | L9: =SUM(B9:C9) -> 26.3425 | M9: =D9 -> 13.229945 | N9: =SUM(E9:G9) -> 50.391121 | O9: =H9 -> 25.611029 | P9: =SUM(L9:O9) -> 115.5746 | R9: BUFFERED BIKE LANE
A10: Bike Lanes | B10: {=SUMPRODUCT(--(Network_Bikeways!$N$11:$N$1010=$R10),Network_Bikeways!$AB$11:$AB$1010,Network_Bikeways!AM$11:AM$1010)} -> 29.101527 | C10: {=SUMPRODUCT(--(Network_Bikeways!$N$11:$N$1010=$R10),Network_Bikeways!$AB$11:$AB$1010,Network_Bikeways!AN$11:AN$1010)} -> 25.438934 | D10: {=SUMPRODUCT(--(Network_Bikeways!$N$11:$N$1010=$R10),Network_Bikeways!$AB$11:$AB$1010,Network_Bikeways!AO$11:AO$1010)} -> 14.215057 | E10: {=SUMPRODUCT(--(Network_Bikeways!$N$11:$N$1010=$R10),Network_Bikeways!$AB$11:$AB$1010,Network_Bikeways!AP$11:AP$1010)} -> 13.26998 | F10: {=SUMPRODUCT(--(Network_Bikeways!$N$11:$N$1010=$R10),Network_Bikeways!$AB$11:$AB$1010,Network_Bikeways!AQ$11:AQ$1010)} -> 7.2915513 | G10: {=SUMPRODUCT(--(Network_Bikeways!$N$11:$N$1010=$R10),Network_Bikeways!$AB$11:$AB$1010,Network_Bikeways!AR$11:AR$1010)} -> 13.993172 | H10: {=SUMPRODUCT(--(Network_Bikeways!$N$11:$N$1010=$R10),Network_Bikeways!$AB$11:$AB$1010,Network_Bikeways!AS$11:AS$1010)} -> 21.782756 | I10: =SUM(B10:H10) -> 125.09298 | K10: Bike Lanes | L10: =SUM(B10:C10) -> 54.540461 | M10: =D10 -> 14.215057 | N10: =SUM(E10:G10) -> 34.554704 | O10: =H10 -> 21.782756 | P10: =SUM(L10:O10) -> 125.09298 | R10: BIKE LANE
A11: Neighborhood Greenways | B11: {=SUMPRODUCT(--(Network_Bikeways!$N$11:$N$1010=$R11),Network_Bikeways!$AB$11:$AB$1010,Network_Bikeways!AM$11:AM$1010)} -> 13.89704 | C11: {=SUMPRODUCT(--(Network_Bikeways!$N$11:$N$1010=$R11),Network_Bikeways!$AB$11:$AB$1010,Network_Bikeways!AN$11:AN$1010)} -> 8.4924731 | D11: {=SUMPRODUCT(--(Network_Bikeways!$N$11:$N$1010=$R11),Network_Bikeways!$AB$11:$AB$1010,Network_Bikeways!AO$11:AO$1010)} -> 8.6537416 | E11: {=SUMPRODUCT(--(Network_Bikeways!$N$11:$N$1010=$R11),Network_Bikeways!$AB$11:$AB$1010,Network_Bikeways!AP$11:AP$1010)} -> 0 | F11: {=SUMPRODUCT(--(Network_Bikeways!$N$11:$N$1010=$R11),Network_Bikeways!$AB$11:$AB$1010,Network_Bikeways!AQ$11:AQ$1010)} -> 0 | G11: {=SUMPRODUCT(--(Network_Bikeways!$N$11:$N$1010=$R11),Network_Bikeways!$AB$11:$AB$1010,Network_Bikeways!AR$11:AR$1010)} -> 3.5877711 | H11: {=SUMPRODUCT(--(Network_Bikeways!$N$11:$N$1010=$R11),Network_Bikeways!$AB$11:$AB$1010,Network_Bikeways!AS$11:AS$1010)} -> 3.2810998 | I11: =SUM(B11:H11) -> 37.912126 | K11: Neighborhood Greenways | L11: =SUM(B11:C11) -> 22.389513 | M11: =D11 -> 8.6537416 | N11: =SUM(E11:G11) -> 3.5877711 | O11: =H11 -> 3.2810998 | P11: =SUM(L11:O11) -> 37.912126 | R11: NEIGHBORHOOD GREENWAY
A12: Marked Shared Lanes | B12: {=SUMPRODUCT(--(Network_Bikeways!$N$11:$N$1010=$R12),Network_Bikeways!$AB$11:$AB$1010,Network_Bikeways!AM$11:AM$1010)} -> 12.136764 | C12: {=SUMPRODUCT(--(Network_Bikeways!$N$11:$N$1010=$R12),Network_Bikeways!$AB$11:$AB$1010,Network_Bikeways!AN$11:AN$1010)} -> 8.8243776 | D12: {=SUMPRODUCT(--(Network_Bikeways!$N$11:$N$1010=$R12),Network_Bikeways!$AB$11:$AB$1010,Network_Bikeways!AO$11:AO$1010)} -> 3.4280644 | E12: {=SUMPRODUCT(--(Network_Bikeways!$N$11:$N$1010=$R12),Network_Bikeways!$AB$11:$AB$1010,Network_Bikeways!AP$11:AP$1010)} -> 5.7598033 | F12: {=SUMPRODUCT(--(Network_Bikeways!$N$11:$N$1010=$R12),Network_Bikeways!$AB$11:$AB$1010,Network_Bikeways!AQ$11:AQ$1010)} -> 6.5614027 | G12: {=SUMPRODUCT(--(Network_Bikeways!$N$11:$N$1010=$R12),Network_Bikeways!$AB$11:$AB$1010,Network_Bikeways!AR$11:AR$1010)} -> 7.99871 | H12: {=SUMPRODUCT(--(Network_Bikeways!$N$11:$N$1010=$R12),Network_Bikeways!$AB$11:$AB$1010,Network_Bikeways!AS$11:AS$1010)} -> 5.2765018 | I12: =SUM(B12:H12) -> 49.985623 | K12: Marked Shared Lanes | L12: =SUM(B12:C12) -> 20.961141 | M12: =D12 -> 3.4280644 | N12: =SUM(E12:G12) -> 20.319916 | O12: =H12 -> 5.2765018 | P12: =SUM(L12:O12) -> 49.985623 | R12: SHARED-LANE
A13: TOTAL | B13: =SUM(B8:B12) -> 65.441814 | C13: =SUM(C8:C12) -> 63.96901 | D13: =SUM(D8:D12) -> 48.50289 | E13: =SUM(E8:E12) -> 45.328503 | F13: =SUM(F8:F12) -> 26.351077 | G13: =SUM(G8:G12) -> 45.75736 | H13: =SUM(H8:H12) -> 71.723329 | I13: =SUM(I8:I12) -> 367.07398 | K13: TOTAL | L13: =SUM(L8:L12) -> 129.41082 | M13: =SUM(M8:M12) -> 48.50289 | N13: =SUM(N8:N12) -> 117.43694 | O13: =SUM(O8:O12) -> 71.723329 | P13: =SUM(P8:P12) -> 367.07398
A15: all but Shared Lanes | B15: =SUM(B8:B11) -> 53.305051 | C15: =SUM(C8:C11) -> 55.144633 | D15: =SUM(D8:D11) -> 45.074825 | E15: =SUM(E8:E11) -> 39.5687 | F15: =SUM(F8:F11) -> 19.789674 | G15: =SUM(G8:G11) -> 37.75865 | H15: =SUM(H8:H11) -> 66.446827 | I15: =SUM(I8:I11) -> 317.08836 | K15: all but Shared Lanes | L15: =SUM(L8:L11) -> 108.44968 | M15: =SUM(M8:M11) -> 45.074825 | N15: =SUM(N8:N11) -> 97.117023 | O15: =SUM(O8:O11) -> 66.446827 | P15: =SUM(P8:P11) -> 317.08836
A18: Share of Facilities by Geography | K18: Share of Facilities by Geography
A19: Protected Bike Lanes | B19: =B8/$I8 -> 0.057854379 | C19: =C8/$I8 -> 0.076588334 | D19: =D8/$I8 -> 0.23309255 | E19: =E8/$I8 -> 0.074198324 | F19: =F8/$I8 -> 0.022130065 | G19: =G8/$I8 -> 0.12656763 | H19: =H8/$I8 -> 0.40956871 | I19: =I8/$I8 -> 1 | K19: Protected Bike Lanes | L19: =L8/$P8 -> 0.13444271 | M19: =M8/$P8 -> 0.23309255 | N19: =N8/$P8 -> 0.22289602 | O19: =O8/$P8 -> 0.40956871 | P19: =P8/$P8 -> 1 | R19: PROTECTED BIKE LANE
A20: Buffered Bike Lanes | B20: =B9/$I9 -> 0.06989935 | C20: =C9/$I9 -> 0.15802704 | D20: =D9/$I9 -> 0.11447105 | E20: =E9/$I9 -> 0.20282521 | F20: =F9/$I9 -> 0.10076543 | G20: =G9/$I9 -> 0.13241454 | H20: =H9/$I9 -> 0.22159739 | I20: =I9/$I9 -> 1 | K20: Buffered Bike Lanes | L20: =L9/$P9 -> 0.22792639 | M20: =M9/$P9 -> 0.11447105 | N20: =N9/$P9 -> 0.43600517 | O20: =O9/$P9 -> 0.22159739 | P20: =P9/$P9 -> 1 | R20: BUFFERED BIKE LANE
A21: Bike Lanes | B21: =B10/$I10 -> 0.23263918 | C21: =C10/$I10 -> 0.20336021 | D21: =D10/$I10 -> 0.11363593 | E21: =E10/$I10 -> 0.10608094 | F21: =F10/$I10 -> 0.058289054 | G21: =G10/$I10 -> 0.11186217 | H21: =H10/$I10 -> 0.17413252 | I21: =I10/$I10 -> 1 | K21: Bike Lanes | L21: =L10/$P10 -> 0.43599939 | M21: =M10/$P10 -> 0.11363593 | N21: =N10/$P10 -> 0.27623216 | O21: =O10/$P10 -> 0.17413252 | P21: =P10/$P10 -> 1 | R21: BIKE LANE
A22: Neighborhood Greenways | B22: =B11/$I11 -> 0.36655924 | C22: =C11/$I11 -> 0.22400414 | D22: =D11/$I11 -> 0.22825789 | E22: =E11/$I11 -> 0 | F22: =F11/$I11 -> 0 | G22: =G11/$I11 -> 0.094633868 | H22: =H11/$I11 -> 0.086544864 | I22: =I11/$I11 -> 1 | K22: Neighborhood Greenways | L22: =L11/$P11 -> 0.59056338 | M22: =M11/$P11 -> 0.22825789 | N22: =N11/$P11 -> 0.094633868 | O22: =O11/$P11 -> 0.086544864 | P22: =P11/$P11 -> 1 | R22: NEIGHBORHOOD GREENWAY
A23: Marked Shared Lanes | B23: =B12/$I12 -> 0.24280509 | C23: =C12/$I12 -> 0.17653831 | D23: =D12/$I12 -> 0.068581007 | E23: =E12/$I12 -> 0.1152292 | F23: =F12/$I12 -> 0.1312658 | G23: =G12/$I12 -> 0.16002021 | H23: =H12/$I12 -> 0.10556039 | I23: =I12/$I12 -> 1 | K23: Marked Shared Lanes | L23: =L12/$P12 -> 0.4193434 | M23: =M12/$P12 -> 0.068581007 | N23: =N12/$P12 -> 0.40651521 | O23: =O12/$P12 -> 0.10556039 | P23: =P12/$P12 -> 1 | R23: SHARED-LANE
A24: TOTAL | B24: =B13/$I13 -> 0.17827963 | C24: =C13/$I13 -> 0.17426735 | D24: =D13/$I13 -> 0.13213383 | E24: =E13/$I13 -> 0.12348601 | F24: =F13/$I13 -> 0.071786827 | G24: =G13/$I13 -> 0.12465433 | H24: =H13/$I13 -> 0.19539203 | I24: =I13/$I13 -> 1 | K24: TOTAL | L24: =L13/$P13 -> 0.35254698 | M24: =M13/$P13 -> 0.13213383 | N24: =N13/$P13 -> 0.31992717 | O24: =O13/$P13 -> 0.19539203 | P24: =P13/$P13 -> 1
A26: all but Shared Lanes | B26: =B15/$I15 -> 0.16810788 | C26: =C15/$I15 -> 0.17390936 | D26: =D15/$I15 -> 0.14215225 | E26: =E15/$I15 -> 0.12478761 | F26: =F15/$I15 -> 0.062410597 | G26: =G15/$I15 -> 0.11907927 | H26: =H15/$I15 -> 0.20955303 | I26: =I15/$I15 -> 1 | K26: all but Shared Lanes | L26: =L15/$P15 -> 0.34201723 | M26: =M15/$P15 -> 0.14215225 | N26: =N15/$P15 -> 0.30627748 | O26: =O15/$P15 -> 0.20955303 | P26: =P15/$P15 -> 1
A29: Census | I29: Source: 2016 ACS 5-Year (Updated 8/27/2018) | K29: Census | P29: Source: 2016 ACS 5-Year (Updated 8/27/2018)
A30: Area | B30: =SUMIFS(Geographies!$G$6:$G$809,Geographies!$J$6:$J$809,B$5) -> 20.344508 | C30: =SUMIFS(Geographies!$G$6:$G$809,Geographies!$J$6:$J$809,C$5) -> 51.254445 | D30: =SUMIFS(Geographies!$G$6:$G$809,Geographies!$J$6:$J$809,D$5) -> 21.787325 | E30: =SUMIFS(Geographies!$G$6:$G$809,Geographies!$J$6:$J$809,E$5) -> 28.346796 | F30: =SUMIFS(Geographies!$G$6:$G$809,Geographies!$J$6:$J$809,F$5) -> 40.776885 | G30: =SUMIFS(Geographies!$G$6:$G$809,Geographies!$J$6:$J$809,G$5) -> 49.084347 | H30: =SUMIFS(Geographies!$G$6:$G$809,Geographies!$J$6:$J$809,H$5) -> 19.337014 | I30: =SUM(B30:H30) -> 230.93132 | K30: Area | L30: =SUM(B30:C30) -> 71.598953 | M30: =D30 -> 21.787325 | N30: =SUM(E30:G30) -> 118.20803 | O30: =H30 -> 19.337014 | P30: =SUM(L30:O30) -> 230.93132
A31: Percentage | B31: =B30/$I$30 -> 0.088097655 | C31: =C30/$I$30 -> 0.2219467 | D31: =D30/$I$30 -> 0.094345476 | E31: =E30/$I$30 -> 0.1227499 | F31: =F30/$I$30 -> 0.17657581 | G31: =G30/$I$30 -> 0.21254954 | H31: =H30/$I$30 -> 0.083734912 | I31: =I30/$I$30 -> 1 | K31: Percentage | L31: =L30/$P$30 -> 0.31004436 | M31: =M30/$P$30 -> 0.094345476 | N31: =N30/$P$30 -> 0.51187525 | O31: =O30/$P$30 -> 0.083734912 | P31: =P30/$P$30 -> 1
A32: Population | B32: =SUMIFS(Geographies!$L$6:$L$809,Geographies!$J$6:$J$809,B$5) -> #VALUE! | C32: =SUMIFS(Geographies!$L$6:$L$809,Geographies!$J$6:$J$809,C$5) -> #VALUE! | D32: =SUMIFS(Geographies!$L$6:$L$809,Geographies!$J$6:$J$809,D$5) -> #VALUE! | E32: =SUMIFS(Geographies!$L$6:$L$809,Geographies!$J$6:$J$809,E$5) -> #VALUE! | F32: =SUMIFS(Geographies!$L$6:$L$809,Geographies!$J$6:$J$809,F$5) -> #VALUE! | G32: =SUMIFS(Geographies!$L$6:$L$809,Geographies!$J$6:$J$809,G$5) -> #VALUE! | H32: =SUMIFS(Geographies!$L$6:$L$809,Geographies!$J$6:$J$809,H$5) -> #VALUE! | I32: =SUM(B32:H32) -> #VALUE! | K32: Population | L32: =SUM(B32:C32) -> #VALUE! | M32: =D32 -> #VALUE! | N32: =SUM(E32:G32) -> #VALUE! | O32: =H32 -> #VALUE! | P32: =SUM(L32:O32) -> #VALUE!
A33: Percentage | B33: =B32/$I$32 -> #VALUE! | C33: =C32/$I$32 -> #VALUE! | D33: =D32/$I$32 -> #VALUE! | E33: =E32/$I$32 -> #VALUE! | F33: =F32/$I$32 -> #VALUE! | G33: =G32/$I$32 -> #VALUE! | H33: =H32/$I$32 -> #VALUE! | I33: =I32/$I$32 -> #VALUE! | K33: Percentage | L33: =L32/$P$32 -> #VALUE! | M33: =M32/$P$32 -> #VALUE! | N33: =N32/$P$32 -> #VALUE! | O33: =O32/$P$32 -> #VALUE! | P33: =P32/$P$32 -> #VALUE!
A34: Density | B34: =B32/B30 -> #VALUE! | C34: =C32/C30 -> #VALUE! | D34: =D32/D30 -> #VALUE! | E34: =E32/E30 -> #VALUE! | F34: =F32/F30 -> #VALUE! | G34: =G32/G30 -> #VALUE! | H34: =H32/H30 -> #VALUE! | I34: =I32/I30 -> #VALUE! | K34: Density | L34: =L32/L30 -> #VALUE! | M34: =M32/M30 -> #VALUE! | N34: =N32/N30 -> #VALUE! | O34: =O32/O30 -> #VALUE! | P34: =P32/P30 -> #VALUE!
A36: Automobile | B36: =SUMIFS(Geographies!$N$6:$N$809,Geographies!$J$6:$J$809,B$5) -> #VALUE! | C36: =SUMIFS(Geographies!$N$6:$N$809,Geographies!$J$6:$J$809,C$5) -> #VALUE! | D36: =SUMIFS(Geographies!$N$6:$N$809,Geographies!$J$6:$J$809,D$5) -> #VALUE! | E36: =SUMIFS(Geographies!$N$6:$N$809,Geographies!$J$6:$J$809,E$5) -> #VALUE! | F36: =SUMIFS(Geographies!$N$6:$N$809,Geographies!$J$6:$J$809,F$5) -> #VALUE! | G36: =SUMIFS(Geographies!$N$6:$N$809,Geographies!$J$6:$J$809,G$5) -> #VALUE! | H36: =SUMIFS(Geographies!$N$6:$N$809,Geographies!$J$6:$J$809,H$5) -> #VALUE! | I36: =SUM(B36:H36) -> #VALUE! | K36: Automobile | L36: =SUM(B36:C36) -> #VALUE! | M36: =D36 -> #VALUE! | N36: =SUM(E36:G36) -> #VALUE! | O36: =H36 -> #VALUE! | P36: =SUM(L36:O36) -> #VALUE!
A37: Transit | B37: =SUMIFS(Geographies!$O$6:$O$809,Geographies!$J$6:$J$809,B$5) -> #VALUE! | C37: =SUMIFS(Geographies!$O$6:$O$809,Geographies!$J$6:$J$809,C$5) -> #VALUE! | D37: =SUMIFS(Geographies!$O$6:$O$809,Geographies!$J$6:$J$809,D$5) -> #VALUE! | E37: =SUMIFS(Geographies!$O$6:$O$809,Geographies!$J$6:$J$809,E$5) -> #VALUE! | F37: =SUMIFS(Geographies!$O$6:$O$809,Geographies!$J$6:$J$809,F$5) -> #VALUE! | G37: =SUMIFS(Geographies!$O$6:$O$809,Geographies!$J$6:$J$809,G$5) -> #VALUE! | H37: =SUMIFS(Geographies!$O$6:$O$809,Geographies!$J$6:$J$809,H$5) -> #VALUE! | I37: =SUM(B37:H37) -> #VALUE! | K37: Transit | L37: =SUM(B37:C37) -> #VALUE! | M37: =D37 -> #VALUE! | N37: =SUM(E37:G37) -> #VALUE! | O37: =H37 -> #VALUE! | P37: =SUM(L37:O37) -> #VALUE!
A38: Taxi | B38: =SUMIFS(Geographies!$P$6:$P$809,Geographies!$J$6:$J$809,B$5) -> #VALUE! | C38: =SUMIFS(Geographies!$P$6:$P$809,Geographies!$J$6:$J$809,C$5) -> #VALUE! | D38: =SUMIFS(Geographies!$P$6:$P$809,Geographies!$J$6:$J$809,D$5) -> #VALUE! | E38: =SUMIFS(Geographies!$P$6:$P$809,Geographies!$J$6:$J$809,E$5) -> #VALUE! | F38: =SUMIFS(Geographies!$P$6:$P$809,Geographies!$J$6:$J$809,F$5) -> #VALUE! | G38: =SUMIFS(Geographies!$P$6:$P$809,Geographies!$J$6:$J$809,G$5) -> #VALUE! | H38: =SUMIFS(Geographies!$P$6:$P$809,Geographies!$J$6:$J$809,H$5) -> #VALUE! | I38: =SUM(B38:H38) -> #VALUE! | K38: Taxi | L38: =SUM(B38:C38) -> #VALUE! | M38: =D38 -> #VALUE! | N38: =SUM(E38:G38) -> #VALUE! | O38: =H38 -> #VALUE! | P38: =SUM(L38:O38) -> #VALUE!
A39: Bike | B39: =SUMIFS(Geographies!$Q$6:$Q$809,Geographies!$J$6:$J$809,B$5) -> #VALUE! | C39: =SUMIFS(Geographies!$Q$6:$Q$809,Geographies!$J$6:$J$809,C$5) -> #VALUE! | D39: =SUMIFS(Geographies!$Q$6:$Q$809,Geographies!$J$6:$J$809,D$5) -> #VALUE! | E39: =SUMIFS(Geographies!$Q$6:$Q$809,Geographies!$J$6:$J$809,E$5) -> #VALUE! | F39: =SUMIFS(Geographies!$Q$6:$Q$809,Geographies!$J$6:$J$809,F$5) -> #VALUE! | G39: =SUMIFS(Geographies!$Q$6:$Q$809,Geographies!$J$6:$J$809,G$5) -> #VALUE! | H39: =SUMIFS(Geographies!$Q$6:$Q$809,Geographies!$J$6:$J$809,H$5) -> #VALUE! | I39: =SUM(B39:H39) -> #VALUE! | K39: Bike | L39: =SUM(B39:C39) -> #VALUE! | M39: =D39 -> #VALUE! | N39: =SUM(E39:G39) -> #VALUE! | O39: =H39 -> #VALUE! | P39: =SUM(L39:O39) -> #VALUE!
A40: Walk | B40: =SUMIFS(Geographies!$R$6:$R$809,Geographies!$J$6:$J$809,B$5) -> #VALUE! | C40: =SUMIFS(Geographies!$R$6:$R$809,Geographies!$J$6:$J$809,C$5) -> #VALUE! | D40: =SUMIFS(Geographies!$R$6:$R$809,Geographies!$J$6:$J$809,D$5) -> #VALUE! | E40: =SUMIFS(Geographies!$R$6:$R$809,Geographies!$J$6:$J$809,E$5) -> #VALUE! | F40: =SUMIFS(Geographies!$R$6:$R$809,Geographies!$J$6:$J$809,F$5) -> #VALUE! | G40: =SUMIFS(Geographies!$R$6:$R$809,Geographies!$J$6:$J$809,G$5) -> #VALUE! | H40: =SUMIFS(Geographies!$R$6:$R$809,Geographies!$J$6:$J$809,H$5) -> #VALUE! | I40: =SUM(B40:H40) -> #VALUE! | K40: Walk | L40: =SUM(B40:C40) -> #VALUE! | M40: =D40 -> #VALUE! | N40: =SUM(E40:G40) -> #VALUE! | O40: =H40 -> #VALUE! | P40: =SUM(L40:O40) -> #VALUE!
A41: Other | B41: =SUMIFS(Geographies!$S$6:$S$809,Geographies!$J$6:$J$809,B$5) -> #VALUE! | C41: =SUMIFS(Geographies!$S$6:$S$809,Geographies!$J$6:$J$809,C$5) -> #VALUE! | D41: =SUMIFS(Geographies!$S$6:$S$809,Geographies!$J$6:$J$809,D$5) -> #VALUE! | E41: =SUMIFS(Geographies!$S$6:$S$809,Geographies!$J$6:$J$809,E$5) -> #VALUE! | F41: =SUMIFS(Geographies!$S$6:$S$809,Geographies!$J$6:$J$809,F$5) -> #VALUE! | G41: =SUMIFS(Geographies!$S$6:$S$809,Geographies!$J$6:$J$809,G$5) -> #VALUE! | H41: =SUMIFS(Geographies!$S$6:$S$809,Geographies!$J$6:$J$809,H$5) -> #VALUE! | I41: =SUM(B41:H41) -> #VALUE! | K41: Other | L41: =SUM(B41:C41) -> #VALUE! | M41: =D41 -> #VALUE! | N41: =SUM(E41:G41) -> #VALUE! | O41: =H41 -> #VALUE! | P41: =SUM(L41:O41) -> #VALUE!
A42: TOTAL COMMUTERS | B42: =SUMIFS(Geographies!$M$6:$M$809,Geographies!$J$6:$J$809,B$5) -> #VALUE! | C42: =SUMIFS(Geographies!$M$6:$M$809,Geographies!$J$6:$J$809,C$5) -> #VALUE! | D42: =SUMIFS(Geographies!$M$6:$M$809,Geographies!$J$6:$J$809,D$5) -> #VALUE! | E42: =SUMIFS(Geographies!$M$6:$M$809,Geographies!$J$6:$J$809,E$5) -> #VALUE! | F42: =SUMIFS(Geographies!$M$6:$M$809,Geographies!$J$6:$J$809,F$5) -> #VALUE! | G42: =SUMIFS(Geographies!$M$6:$M$809,Geographies!$J$6:$J$809,G$5) -> #VALUE! | H42: =SUMIFS(Geographies!$M$6:$M$809,Geographies!$J$6:$J$809,H$5) -> #VALUE! | I42: =SUM(B42:H42) -> #VALUE! | K42: TOTAL COMMUTERS | L42: =SUM(B42:C42) -> #VALUE! | M42: =D42 -> #VALUE! | N42: =SUM(E42:G42) -> #VALUE! | O42: =H42 -> #VALUE! | P42: =SUM(L42:O42) -> #VALUE!
A44: Automobile | B44: =B36/B$42 -> #VALUE! | C44: =C36/C$42 -> #VALUE! | D44: =D36/D$42 -> #VALUE! | E44: =E36/E$42 -> #VALUE! | F44: =F36/F$42 -> #VALUE! | G44: =G36/G$42 -> #VALUE! | H44: =H36/H$42 -> #VALUE! | I44: =I36/I$42 -> #VALUE! | K44: Automobile | L44: =L36/L$42 -> #VALUE! | M44: =M36/M$42 -> #VALUE! | N44: =N36/N$42 -> #VALUE! | O44: =O36/O$42 -> #VALUE! | P44: =P36/P$42 -> #VALUE!
A45: Transit | B45: =B37/B$42 -> #VALUE! | C45: =C37/C$42 -> #VALUE! | D45: =D37/D$42 -> #VALUE! | E45: =E37/E$42 -> #VALUE! | F45: =F37/F$42 -> #VALUE! | G45: =G37/G$42 -> #VALUE! | H45: =H37/H$42 -> #VALUE! | I45: =I37/I$42 -> #VALUE! | K45: Transit | L45: =L37/L$42 -> #VALUE! | M45: =M37/M$42 -> #VALUE! | N45: =N37/N$42 -> #VALUE! | O45: =O37/O$42 -> #VALUE! | P45: =P37/P$42 -> #VALUE!
A46: Taxi | B46: =B38/B$42 -> #VALUE! | C46: =C38/C$42 -> #VALUE! | D46: =D38/D$42 -> #VALUE! | E46: =E38/E$42 -> #VALUE! | F46: =F38/F$42 -> #VALUE! | G46: =G38/G$42 -> #VALUE! | H46: =H38/H$42 -> #VALUE! | I46: =I38/I$42 -> #VALUE! | K46: Taxi | L46: =L38/L$42 -> #VALUE! | M46: =M38/M$42 -> #VALUE! | N46: =N38/N$42 -> #VALUE! | O46: =O38/O$42 -> #VALUE! | P46: =P38/P$42 -> #VALUE!
A47: Bike | B47: =B39/B$42 -> #VALUE! | C47: =C39/C$42 -> #VALUE! | D47: =D39/D$42 -> #VALUE! | E47: =E39/E$42 -> #VALUE! | F47: =F39/F$42 -> #VALUE! | G47: =G39/G$42 -> #VALUE! | H47: =H39/H$42 -> #VALUE! | I47: =I39/I$42 -> #VALUE! | K47: Bike | L47: =L39/L$42 -> #VALUE! | M47: =M39/M$42 -> #VALUE! | N47: =N39/N$42 -> #VALUE! | O47: =O39/O$42 -> #VALUE! | P47: =P39/P$42 -> #VALUE!
A48: Walk | B48: =B40/B$42 -> #VALUE! | C48: =C40/C$42 -> #VALUE! | D48: =D40/D$42 -> #VALUE! | E48: =E40/E$42 -> #VALUE! | F48: =F40/F$42 -> #VALUE! | G48: =G40/G$42 -> #VALUE! | H48: =H40/H$42 -> #VALUE! | I48: =I40/I$42 -> #VALUE! | K48: Walk | L48: =L40/L$42 -> #VALUE! | M48: =M40/M$42 -> #VALUE! | N48: =N40/N$42 -> #VALUE! | O48: =O40/O$42 -> #VALUE! | P48: =P40/P$42 -> #VALUE!
A49: Other | B49: =B41/B$42 -> #VALUE! | C49: =C41/C$42 -> #VALUE! | D49: =D41/D$42 -> #VALUE! | E49: =E41/E$42 -> #VALUE! | F49: =F41/F$42 -> #VALUE! | G49: =G41/G$42 -> #VALUE! | H49: =H41/H$42 -> #VALUE! | I49: =I41/I$42 -> #VALUE! | K49: Other | L49: =L41/L$42 -> #VALUE! | M49: =M41/M$42 -> #VALUE! | N49: =N41/N$42 -> #VALUE! | O49: =O41/O$42 -> #VALUE! | P49: =P41/P$42 -> #VALUE!
...

Sheet Geographies
A1: Geographies
A2: for Equity Tracking
H3: Assign Community Area & Equity District | L3: 2020 ACS 5-Year B08301 | T3: Population within a 1/2 mile of
M4: B08301_001E | N4: B08301_002E | O4: B08301_010E | P4: B08301_016E | Q4: B08301_018E | R4: B08301_019E | T4: All Bikeways | V4: > MSL | X4: Low Stress | Z4: Low Stress & Trails
A5: CENSUS_TRACT | B5: CENSUS_TRACT_FULL | C5: TRACT_FIPS | D5: TRACT_CENSUS_YEAR | E5: Community Area | F5: SHAPE.AREA | G5: Sq Miles | H5: Area Name | I5: Group | J5: Region | K5: District | L5: Population | M5: Workers | N5: Automobile | O5: Transit | P5: Taxi | Q5: Bike | R5: Walk | S5: Other | T5: Sq Miles | U5: Population | V5: Sq Miles | W5: Population | X5: Sq Miles | Y5: Population | Z5: Sq Miles | AA5: Population
A6: 350400 | B6: 17031350400 | C6: 17031 | D6: 2010 | E6: 35 | F6: 2163073.4 | G6: 0.077589581 | H6: =_xlfn.IFNA( INDEX(CA!B$2:B$78,MATCH($E6,CA!$A$2:$A$78,0)), "") -> DOUGLAS | I6: =_xlfn.IFNA( INDEX(CA!C$2:C$78,MATCH($E6,CA!$A$2:$A$78,0)), "") -> 6-A | J6: =_xlfn.IFNA( INDEX(CA!D$2:D$78,MATCH($E6,CA!$A$2:$A$78,0)), "") -> 6 | K6: =_xlfn.IFNA( INDEX(CA!E$2:E$78,MATCH($E6,CA!$A$2:$A$78,0)), "") -> SOUTH | L6: #VALUE! | M6: #VALUE! | N6: #VALUE! | O6: #VALUE! | P6: #VALUE! | Q6: #VALUE! | R6: #VALUE! | S6: #VALUE! | T6: 0.07758958 | U6: =(T6/$G6)*$L6 -> #VALUE! | V6: 0.07758958 | W6: =(V6/$G6)*$L6 -> #VALUE! | X6: 0.07758958 | Y6: =(X6/$G6)*$L6 -> #VALUE! | Z6: 0.07758958 | AA6: =(Z6/$G6)*$L6 -> #VALUE!
A7: 839500 | B7: 17031839500 | C7: 17031 | D7: 2010 | E7: 35 | F7: 2825468.3 | G7: 0.10134973 | H7: =_xlfn.IFNA( INDEX(CA!B$2:B$78,MATCH($E7,CA!$A$2:$A$78,0)), "") -> DOUGLAS | I7: =_xlfn.IFNA( INDEX(CA!C$2:C$78,MATCH($E7,CA!$A$2:$A$78,0)), "") -> 6-A | J7: =_xlfn.IFNA( INDEX(CA!D$2:D$78,MATCH($E7,CA!$A$2:$A$78,0)), "") -> 6 | K7: =_xlfn.IFNA( INDEX(CA!E$2:E$78,MATCH($E7,CA!$A$2:$A$78,0)), "") -> SOUTH | L7: #VALUE! | M7: #VALUE! | N7: #VALUE! | O7: #VALUE! | P7: #VALUE! | Q7: #VALUE! | R7: #VALUE! | S7: #VALUE! | T7: 0.10134973 | U7: =(T7/$G7)*$L7 -> #VALUE! | V7: 0.10134973 | W7: =(V7/$G7)*$L7 -> #VALUE! | X7: 0.10134973 | Y7: =(X7/$G7)*$L7 -> #VALUE! | Z7: 0.10134973 | AA7: =(Z7/$G7)*$L7 -> #VALUE!
A8: 839600 | B8: 17031839600 | C8: 17031 | D8: 2010 | E8: 35 | F8: 3518755 | G8: 0.12621797 | H8: =_xlfn.IFNA( INDEX(CA!B$2:B$78,MATCH($E8,CA!$A$2:$A$78,0)), "") -> DOUGLAS | I8: =_xlfn.IFNA( INDEX(CA!C$2:C$78,MATCH($E8,CA!$A$2:$A$78,0)), "") -> 6-A | J8: =_xlfn.IFNA( INDEX(CA!D$2:D$78,MATCH($E8,CA!$A$2:$A$78,0)), "") -> 6 | K8: =_xlfn.IFNA( INDEX(CA!E$2:E$78,MATCH($E8,CA!$A$2:$A$78,0)), "") -> SOUTH | L8: #VALUE! | M8: #VALUE! | N8: #VALUE! | O8: #VALUE! | P8: #VALUE! | Q8: #VALUE! | R8: #VALUE! | S8: #VALUE! | T8: 0.12621797 | U8: =(T8/$G8)*$L8 -> #VALUE! | V8: 0.12621797 | W8: =(V8/$G8)*$L8 -> #VALUE! | X8: 0.12621797 | Y8: =(X8/$G8)*$L8 -> #VALUE! | Z8: 0.12621797 | AA8: =(Z8/$G8)*$L8 -> #VALUE!
A9: 842000 | B9: 17031842000 | C9: 17031 | D9: 2010 | E9: 35 | F9: 6328580.6 | G9: 0.22700659 | H9: =_xlfn.IFNA( INDEX(CA!B$2:B$78,MATCH($E9,CA!$A$2:$A$78,0)), "") -> DOUGLAS | I9: =_xlfn.IFNA( INDEX(CA!C$2:C$78,MATCH($E9,CA!$A$2:$A$78,0)), "") -> 6-A | J9: =_xlfn.IFNA( INDEX(CA!D$2:D$78,MATCH($E9,CA!$A$2:$A$78,0)), "") -> 6 | K9: =_xlfn.IFNA( INDEX(CA!E$2:E$78,MATCH($E9,CA!$A$2:$A$78,0)), "") -> SOUTH | L9: #VALUE! | M9: #VALUE! | N9: #VALUE! | O9: #VALUE! | P9: #VALUE! | Q9: #VALUE! | R9: #VALUE! | S9: #VALUE! | T9: 0.2270066 | U9: =(T9/$G9)*$L9 -> #VALUE! | V9: 0.2270066 | W9: =(V9/$G9)*$L9 -> #VALUE! | X9: 0.2270066 | Y9: =(X9/$G9)*$L9 -> #VALUE! | Z9: 0.2270066 | AA9: =(Z9/$G9)*$L9 -> #VALUE!
A10: 839200 | B10: 17031839200 | C10: 17031 | D10: 2010 | E10: 35 | F10: 7006617.4 | G10: 0.25132782 | H10: =_xlfn.IFNA( INDEX(CA!B$2:B$78,MATCH($E10,CA!$A$2:$A$78,0)), "") -> DOUGLAS | I10: =_xlfn.IFNA( INDEX(CA!C$2:C$78,MATCH($E10,CA!$A$2:$A$78,0)), "") -> 6-A | J10: =_xlfn.IFNA( INDEX(CA!D$2:D$78,MATCH($E10,CA!$A$2:$A$78,0)), "") -> 6 | K10: =_xlfn.IFNA( INDEX(CA!E$2:E$78,MATCH($E10,CA!$A$2:$A$78,0)), "") -> SOUTH | L10: #VALUE! | M10: #VALUE! | N10: #VALUE! | O10: #VALUE! | P10: #VALUE! | Q10: #VALUE! | R10: #VALUE! | S10: #VALUE! | T10: 0.25132782 | U10: =(T10/$G10)*$L10 -> #VALUE! | V10: 0.25132782 | W10: =(V10/$G10)*$L10 -> #VALUE! | X10: 0.25132782 | Y10: =(X10/$G10)*$L10 -> #VALUE! | Z10: 0.25132782 | AA10: =(Z10/$G10)*$L10 -> #VALUE!
A11: 351000 | B11: 17031351000 | C11: 17031 | D11: 2010 | E11: 35 | F11: 8900946.2 | G11: 0.31927751 | H11: =_xlfn.IFNA( INDEX(CA!B$2:B$78,MATCH($E11,CA!$A$2:$A$78,0)), "") -> DOUGLAS | I11: =_xlfn.IFNA( INDEX(CA!C$2:C$78,MATCH($E11,CA!$A$2:$A$78,0)), "") -> 6-A | J11: =_xlfn.IFNA( INDEX(CA!D$2:D$78,MATCH($E11,CA!$A$2:$A$78,0)), "") -> 6 | K11: =_xlfn.IFNA( INDEX(CA!E$2:E$78,MATCH($E11,CA!$A$2:$A$78,0)), "") -> SOUTH | L11: #VALUE! | M11: #VALUE! | N11: #VALUE! | O11: #VALUE! | P11: #VALUE! | Q11: #VALUE! | R11: #VALUE! | S11: #VALUE! | T11: 0.31927751 | U11: =(T11/$G11)*$L11 -> #VALUE! | V11: 0.31927751 | W11: =(V11/$G11)*$L11 -> #VALUE! | X11: 0.31927751 | Y11: =(X11/$G11)*$L11 -> #VALUE! | Z11: 0.31927751 | AA11: =(Z11/$G11)*$L11 -> #VALUE!
A12: 351500 | B12: 17031351500 | C12: 17031 | D12: 2010 | E12: 35 | F12: 1818880.8 | G12: 0.065243372 | H12: =_xlfn.IFNA( INDEX(CA!B$2:B$78,MATCH($E12,CA!$A$2:$A$78,0)), "") -> DOUGLAS | I12: =_xlfn.IFNA( INDEX(CA!C$2:C$78,MATCH($E12,CA!$A$2:$A$78,0)), "") -> 6-A | J12: =_xlfn.IFNA( INDEX(CA!D$2:D$78,MATCH($E12,CA!$A$2:$A$78,0)), "") -> 6 | K12: =_xlfn.IFNA( INDEX(CA!E$2:E$78,MATCH($E12,CA!$A$2:$A$78,0)), "") -> SOUTH | L12: #VALUE! | M12: #VALUE! | N12: #VALUE! | O12: #VALUE! | P12: #VALUE! | Q12: #VALUE! | R12: #VALUE! | S12: #VALUE! | T12: 0.065243373 | U12: =(T12/$G12)*$L12 -> #VALUE! | V12: 0.065208649 | W12: =(V12/$G12)*$L12 -> #VALUE! | X12: 0.065208649 | Y12: =(X12/$G12)*$L12 -> #VALUE! | Z12: 0.065208649 | AA12: =(Z12/$G12)*$L12 -> #VALUE!
A13: 351400 | B13: 17031351400 | C13: 17031 | D13: 2010 | E13: 35 | F13: 3483715.8 | G13: 0.12496111 | H13: =_xlfn.IFNA( INDEX(CA!B$2:B$78,MATCH($E13,CA!$A$2:$A$78,0)), "") -> DOUGLAS | I13: =_xlfn.IFNA( INDEX(CA!C$2:C$78,MATCH($E13,CA!$A$2:$A$78,0)), "") -> 6-A | J13: =_xlfn.IFNA( INDEX(CA!D$2:D$78,MATCH($E13,CA!$A$2:$A$78,0)), "") -> 6 | K13: =_xlfn.IFNA( INDEX(CA!E$2:E$78,MATCH($E13,CA!$A$2:$A$78,0)), "") -> SOUTH | L13: #VALUE! | M13: #VALUE! | N13: #VALUE! | O13: #VALUE! | P13: #VALUE! | Q13: #VALUE! | R13: #VALUE! | S13: #VALUE! | T13: 0.12496111 | U13: =(T13/$G13)*$L13 -> #VALUE! | V13: 0.12496111 | W13: =(V13/$G13)*$L13 -> #VALUE! | X13: 0.12496111 | Y13: =(X13/$G13)*$L13 -> #VALUE! | Z13: 0.12496111 | AA13: =(Z13/$G13)*$L13 -> #VALUE!
A14: 351100 | B14: 17031351100 | C14: 17031 | D14: 2010 | E14: 35 | F14: 3776863.6 | G14: 0.13547634 | H14: =_xlfn.IFNA( INDEX(CA!B$2:B$78,MATCH($E14,CA!$A$2:$A$78,0)), "") -> DOUGLAS | I14: =_xlfn.IFNA( INDEX(CA!C$2:C$78,MATCH($E14,CA!$A$2:$A$78,0)), "") -> 6-A | J14: =_xlfn.IFNA( INDEX(CA!D$2:D$78,MATCH($E14,CA!$A$2:$A$78,0)), "") -> 6 | K14: =_xlfn.IFNA( INDEX(CA!E$2:E$78,MATCH($E14,CA!$A$2:$A$78,0)), "") -> SOUTH | L14: #VALUE! | M14: #VALUE! | N14: #VALUE! | O14: #VALUE! | P14: #VALUE! | Q14: #VALUE! | R14: #VALUE! | S14: #VALUE! | T14: 0.13547634 | U14: =(T14/$G14)*$L14 -> #VALUE! | V14: 0.13547634 | W14: =(V14/$G14)*$L14 -> #VALUE! | X14: 0.13547634 | Y14: =(X14/$G14)*$L14 -> #VALUE! | Z14: 0.13547634 | AA14: =(Z14/$G14)*$L14 -> #VALUE!
A15: 836500 | B15: 17031836500 | C15: 17031 | D15: 2010 | E15: 36 | F15: 5521904.7 | G15: 0.19807108 | H15: =_xlfn.IFNA( INDEX(CA!B$2:B$78,MATCH($E15,CA!$A$2:$A$78,0)), "") -> OAKLAND | I15: =_xlfn.IFNA( INDEX(CA!C$2:C$78,MATCH($E15,CA!$A$2:$A$78,0)), "") -> 6-A | J15: =_xlfn.IFNA( INDEX(CA!D$2:D$78,MATCH($E15,CA!$A$2:$A$78,0)), "") -> 6 | K15: =_xlfn.IFNA( INDEX(CA!E$2:E$78,MATCH($E15,CA!$A$2:$A$78,0)), "") -> SOUTH | L15: #VALUE! | M15: #VALUE! | N15: #VALUE! | O15: #VALUE! | P15: #VALUE! | Q15: #VALUE! | R15: #VALUE! | S15: #VALUE! | T15: 0.19807109 | U15: =(T15/$G15)*$L15 -> #VALUE! | V15: 0.19807109 | W15: =(V15/$G15)*$L15 -> #VALUE! | X15: 0.19807109 | Y15: =(X15/$G15)*$L15 -> #VALUE! | Z15: 0.19807109 | AA15: =(Z15/$G15)*$L15 -> #VALUE!
A16: 360200 | B16: 17031360200 | C16: 17031 | D16: 2010 | E16: 36 | F16: 2514325.2 | G16: 0.090189008 | H16: =_xlfn.IFNA( INDEX(CA!B$2:B$78,MATCH($E16,CA!$A$2:$A$78,0)), "") -> OAKLAND | I16: =_xlfn.IFNA( INDEX(CA!C$2:C$78,MATCH($E16,CA!$A$2:$A$78,0)), "") -> 6-A | J16: =_xlfn.IFNA( INDEX(CA!D$2:D$78,MATCH($E16,CA!$A$2:$A$78,0)), "") -> 6 | K16: =_xlfn.IFNA( INDEX(CA!E$2:E$78,MATCH($E16,CA!$A$2:$A$78,0)), "") -> SOUTH | L16: #VALUE! | M16: #VALUE! | N16: #VALUE! | O16: #VALUE! | P16: #VALUE! | Q16: #VALUE! | R16: #VALUE! | S16: #VALUE! | T16: 0.090189003 | U16: =(T16/$G16)*$L16 -> #VALUE! | V16: 0.090189003 | W16: =(V16/$G16)*$L16 -> #VALUE! | X16: 0.090189003 | Y16: =(X16/$G16)*$L16 -> #VALUE! | Z16: 0.090189003 | AA16: =(Z16/$G16)*$L16 -> #VALUE!
A17: 836400 | B17: 17031836400 | C17: 17031 | D17: 2010 | E17: 36 | F17: 8877731.1 | G17: 0.31844478 | H17: =_xlfn.IFNA( INDEX(CA!B$2:B$78,MATCH($E17,CA!$A$2:$A$78,0)), "") -> OAKLAND | I17: =_xlfn.IFNA( INDEX(CA!C$2:C$78,MATCH($E17,CA!$A$2:$A$78,0)), "") -> 6-A | J17: =_xlfn.IFNA( INDEX(CA!D$2:D$78,MATCH($E17,CA!$A$2:$A$78,0)), "") -> 6 | K17: =_xlfn.IFNA( INDEX(CA!E$2:E$78,MATCH($E17,CA!$A$2:$A$78,0)), "") -> SOUTH | L17: #VALUE! | M17: #VALUE! | N17: #VALUE! | O17: #VALUE! | P17: #VALUE! | Q17: #VALUE! | R17: #VALUE! | S17: #VALUE! | T17: 0.31844478 | U17: =(T17/$G17)*$L17 -> #VALUE! | V17: 0.31844478 | W17: =(V17/$G17)*$L17 -> #VALUE! | X17: 0.31844478 | Y17: =(X17/$G17)*$L17 -> #VALUE! | Z17: 0.31844478 | AA17: =(Z17/$G17)*$L17 -> #VALUE!
... A809: 831000 | B809: 17031831000 | C809: 17031 | D809: 2010 | E809: 22 | F809: 3038813.9 | G809: 0.10900245 | H809: =_xlfn.IFNA( INDEX(CA!B$2:B$78,MATCH($E809,CA!$A$2:$A$78,0)), "") -> LOGAN SQUARE | I809: =_xlfn.IFNA( INDEX(CA!C$2:C$78,MATCH($E809,CA!$A$2:$A$78,0)), "") -> 2-B | J809: =_xlfn.IFNA( INDEX(CA!D$2:D$78,MATCH($E809,CA!$A$2:$A$78,0)), "") -> 2 | K809: =_xlfn.IFNA( INDEX(CA!E$2:E$78,MATCH($E809,CA!$A$2:$A$78,0)), "") -> NORTHWEST | L809: #VALUE! | M809: #VALUE! | N809: #VALUE! | O809: #VALUE! | P809: #VALUE! | Q809: #VALUE! | R809: #VALUE! | S809: #VALUE! | T809: 0.10900245 | U809: =(T809/$G809)*$L809 -> #VALUE! | V809: 0.10900245 | W809: =(V809/$G809)*$L809 -> #VALUE! | X809: 0.10900245 | Y809: =(X809/$G809)*$L809 -> #VALUE! | Z809: 0.10900245 | AA809: =(Z809/$G809)*$L809 -> #VALUE!
A811: Reference formulas - Use these when updating values / linking to source data | G811: =F811/(5280*5280) -> 0 | H811: =_xlfn.IFNA( INDEX(CA!B$2:B$78,MATCH($E811,CA!$A$2:$A$78,0)), "") | I811: =_xlfn.IFNA( INDEX(CA!C$2:C$78,MATCH($E811,CA!$A$2:$A$78,0)), "") | J811: =_xlfn.IFNA( INDEX(CA!D$2:D$78,MATCH($E811,CA!$A$2:$A$78,0)), "") | K811: =_xlfn.IFNA( INDEX(CA!E$2:E$78,MATCH($E811,CA!$A$2:$A$78,0)), "") | L811: 0 | M811: 0 | N811: 0 | O811: 0 | P811: 0 | Q811: 0 | R811: 0 | S811: =M811-SUM(N811:R811) -> 0
L813: =SUM(L6:L809) -> #VALUE! | M813: =SUM(M6:M809) -> #VALUE! | N813: =SUM(N6:N809) -> #VALUE! | O813: =SUM(O6:O809) -> #VALUE! | P813: =SUM(P6:P809) -> #VALUE! | Q813: =SUM(Q6:Q809) -> #VALUE! | R813: =SUM(R6:R809) -> #VALUE! | S813: =SUM(S6:S809) -> #VALUE!
L814: 2739477 | M814: 1276010 | N814: 740643 | O814: 352515 | P814: 7540 | Q814: 20614 | R814: 84786 | S814: 69912

Sheet Tract_2000

Sheet Tract_2010

Sheet Tract_2020

Sheet CA
A1: AREA_NUMBER | B1: AREA_NAME | C1: COM_GROUP | D1: PLAN_DIST | E1: PLAN_REGIO | F1: Mob_Index | G1: EcoH_Index | H1: MobEco_Ind
A2: 1 | B2: ROGERS PARK | C2: 1-A | D2: 1 | E2: NORTH | F2: 33.799999 | G2: 44.099998 | H2: 39
A3: 2 | B3: WEST RIDGE | C3: 1-A | D3: 1 | E3: NORTH | F3: 37.5 | G3: 57.700001 | H3: 47.599998
A4: 3 | B4: UPTOWN | C4: 1-A | D4: 1 | E4: NORTH | F4: 22.9 | G4: 34.400002 | H4: 28.6
A5: 4 | B5: LINCOLN SQUARE | C5: 1-A | D5: 1 | E5: NORTH | F5: 19.200001 | G5: 24.6 | H5: 21.9
A6: 5 | B6: NORTH CENTER | C6: 1-B | D6: 1 | E6: NORTH | F6: 7.3000002 | G6: 19.5 | H6: 13.4
A7: 6 | B7: LAKE VIEW | C7: 1-B | D7: 1 | E7: NORTH | F7: 2.3 | G7: 13.2 | H7: 7.6999998
A8: 7 | B8: LINCOLN PARK | C8: 1-B | D8: 1 | E8: NORTH | F8: 0 | G8: 12 | H8: 6
A9: 77 | B9: EDGEWATER | C9: 1-A | D9: 1 | E9: NORTH | F9: 29.799999 | G9: 32.5 | H9: 31.200001
A10: 9 | B10: EDISON PARK | C10: 2-C | D10: 2 | E10: NORTHWEST | F10: 22.6 | G10: 21.6 | H10: 22.1
A11: 10 | B11: NORWOOD PARK | C11: 2-C | D11: 2 | E11: NORTHWEST | F11: 25.299999 | G11: 29.6 | H11: 27.5
A12: 11 | B12: JEFFERSON PARK | C12: 2-A | D12: 2 | E12: NORTHWEST | F12: 30.9 | G12: 34.400002 | H12: 32.599998
A13: 12 | B13: FOREST GLEN | C13: 2-A | D13: 2 | E13: NORTHWEST | F13: 30.1 | G13: 30.299999 | H13: 30.200001
... A72: 69 | B72: GREATER GRAND CROSSING | C72: 6-B | D72: 6 | E72: SOUTH | F72: 73.599998 | G72: 57.799999 | H72: 65.699997
A73: 8 | B73: NEAR NORTH SIDE | C73: 7 | D73: 7 | E73: CENTRAL | F73: 1.1 | G73: 11.3 | H73: 6.1999998
A74: 24 | B74: WEST TOWN | C74: 3-B | D74: 7 | E74: CENTRAL | F74: 5.5 | G74: 16.799999 | H74: 11.2
A75: 28 | B75: NEAR WEST SIDE | C75: 3-B | D75: 7 | E75: CENTRAL | F75: 14.5 | G75: 29.4 | H75: 21.9
A76: 31 | B76: LOWER WEST SIDE | C76: 3-B | D76: 7 | E76: CENTRAL | F76: 41.599998 | G76: 45.099998 | H76: 43.299999
A77: 32 | B77: LOOP | C77: 7 | D77: 7 | E77: CENTRAL | F77: 2.2 | G77: 14.1 | H77: 8.1000004
A78: 33 | B78: NEAR SOUTH SIDE | C78: 7 | D78: 7 | E78: CENTRAL | F78: 13.4 | G78: 10.3 | H78: 11.8

Sheet ACS Mode Share

Sheet ACS Vehicles

Sheet ACS Car Households

Sheet Bus Ridership

Sheet Rail Ridership

Sheet NTD

Sheet Network_Bikeways
A1: Chicago Bike Network
A2: CDOT Bike Program
B4: 44893 | C4: Date of GIS export
AE8: Formula for MI_LANE
A9: FID | B9: STREET | C9: PRE_DIR | D9: ST_NAME | E9: ST_TYPE | F9: ONEWAY_DIR | G9: L_F_ADDR | H9: R_F_ADDR | I9: F_STREET | J9: L_T_ADDR | K9: R_T_ADDR | L9: T_STREET | M9: CLASS | O9: BIKEROUTE | P9: INST_TYPE | Q9: PROJECT_ID | R9: INST_PRO | S9: INST_YR | T9: INST_MO | U9: INST_NOTES | V9: MAIN_PRO | W9: MAIN_YR | X9: MAIN_MO | Y9: MAIN_NOTES | Z9: RESTRIPED | AA9: RESURFACED | AB9: MI_CTRLINE | AC9: MI_LANE | AD9: BR_NAME | AE9: BR_ONEWAY | AF9: BR_OW_DIR | AG9: CONTRAFLOW | AH9: PBL_ADJ_TW | AI9: PBL_PROTEC | AJ9: PASSING | AK9: CONC_PVMT | AL9: CONC_YR | AM9: EQUITY_N | AN9: EQUITY_NW | AO9: EQUITY_W | AP9: EQUITY_S | AQ9: EQUITY_SW | AR9: EQUITY_FS | AS9: EQUITY_C
